Workbook
Name DD_ENERGY: 배출계수_드롭다운!$B$3:$B$16
Name DD_ENERGY_UNIT: 배출계수_드롭다운!$C$3:$C$7
Name DD_PURCHASE_GROUP: 배출계수_드롭다운!$A$3:$A$19
Name DD_TRANSPORT_DISTANCE: 배출계수_드롭다운!$D$3:$D$9
Name DD_TRANSPORT_SPEND: 배출계수_드롭다운!$E$3:$E$19
Name DD_TRANSPORT_WEIGHT_UNIT: 배출계수_드롭다운!$K$3:$K$4
Name DD_TRAVEL_DISTANCE: 배출계수_드롭다운!$F$3:$F$15
Name DD_TRAVEL_SPEND: 배출계수_드롭다운!$G$3:$G$8
Name DD_WASTE_C5_TYPE: 배출계수_드롭다운!$H$3:$H$18
Name DD_WASTE_METHOD: 배출계수_드롭다운!$I$3:$I$6
Name DD_WASTE_UNIT: 배출계수_드롭다운!$J$3:$J$4
Name DD_APPLIED_COMPANY: 기업정보!$E$2:$E$50

Sheet 기업정보
E1: 회사 목록(관리용)
B2: Scope 3 배출량 산정 템플릿 | E2: 공연공
B4: 기업 정보 입력
B5: - 아래에 적용 기업명을 선택하면, 각 카테고리 시트(C5 폐기물 종류 등) 상단의 '*적용 기업명' 칸과 상세명 자동 매칭에 함께 반영됩니다.
B7: *적용 기업명 | C7: 공연공 | D7: ※ 새 회사를 추가하려면 이 시트 E열에 회사명을 한 줄 추가한 뒤 여기서 선택하세요. 그 회사의 실제 매핑 데이터는 '회사별_폐기물매핑'·'회사별_교통수단매핑' 시트 A~C열에 별도로 추가해야 자동 매칭이 동작합니다.

Sheet C1_구매품서비스
B2: C1. 구매품 및 서비스
B4: 카테고리 정의
B5: - 보고년도에 회사가 구매한 원재료, 부자재, 포장재, 소모품, 사무용품, 외주가공, 서비스/용역 등에서 발생하는 온실가스 배출량
B6: - 자산으로 회계 처리된 설비, 장비, 차량, 건물 등은 C2 자본재에 작성
B9: 작성 기준
B10: 1) 온실가스 산정 식: Σ(구매금액 × 품목/서비스별 배출계수)
B11: - 배출계수는 US EPA Supply Chain Greenhouse Gas Emission Factors v1.3 등 지출기반 배출계수 활용
B12: 2) 품목군은 최종 배출계수 매핑 분류로 사용하므로 가장 가까운 항목을 선택
B13: 3) 상세 품목명/서비스명은 ERP 품목명, 세금계산서, 거래명세서 기준으로 작성
B15: ※ 사용 기준: 월별 자료가 있으면 1월~12월 칸에 입력하고, 연간 총량만 있으면 연간 입력 칸에 입력합니다. 동일 행에서 연간과 월별을 중복 입력하지 마세요.
B16: ※ 주황색으로 표시된 필수 입력칸은 반드시 작성해야 합니다.
B17: ※ 회색으로 표시된 입력란(배출계수, 배출량)은 자동으로 산출되므로 별도로 입력하지 않으셔도 됩니다.
B18: *국가 | C18: *사업장 | D18: *품목군 | E18: *상세 품목명/서비스명 | F18: 계정과목(선택) | G18: 거래처명(선택) | H18: 연간 입력 | I18: 월별 지출금액 | U18: 비고(선택) | V18: 배출계수(kgCO2e/원) | W18: 배출량(tCO2e)
H19: 연간지출금액(원) | I19: 1월 | J19: 2월 | K19: 3월 | L19: 4월 | M19: 5월 | N19: 6월 | O19: 7월 | P19: 8월 | Q19: 9월 | R19: 10월 | S19: 11월 | T19: 12월
B20: 대한민국 | C20: 본사 | D20: 사무용품 | E20: A4 복사용지 | F20: 소모품비 | G20: 문구업체 | H20: =IF(SUM(I20:T20)=0,"",SUM(I20:T20)) | I20: 100000 | J20: 100000 | K20: 100000 | L20: 100000 | M20: 100000 | N20: 100000 | O20: 100000 | P20: 100000 | Q20: 100000 | R20: 100000 | S20: 100000 | T20: 100000 | U20: 사무실 복사용지 | V20: AI 추천 | W20: AI 자동산정
H21: =IF(SUM(I21:T21)=0,"",SUM(I21:T21))
H22: =IF(SUM(I22:T22)=0,"",SUM(I22:T22))
H23: =IF(SUM(I23:T23)=0,"",SUM(I23:T23))
H24: =IF(SUM(I24:T24)=0,"",SUM(I24:T24))
H25: =IF(SUM(I25:T25)=0,"",SUM(I25:T25))
H26: =IF(SUM(I26:T26)=0,"",SUM(I26:T26))
H27: =IF(SUM(I27:T27)=0,"",SUM(I27:T27))
H28: =IF(SUM(I28:T28)=0,"",SUM(I28:T28))
H29: =IF(SUM(I29:T29)=0,"",SUM(I29:T29))
H30: =IF(SUM(I30:T30)=0,"",SUM(I30:T30))
H31: =IF(SUM(I31:T31)=0,"",SUM(I31:T31))
H32: =IF(SUM(I32:T32)=0,"",SUM(I32:T32))
... H55: =IF(SUM(I55:T55)=0,"",SUM(I55:T55))

Sheet C2_자본재
B2: C2. 자본재
B4: 카테고리 정의
B5: - 보고년도에 회사가 취득한 건물, 구축물, 기계장치, 생산설비, 차량, IT장비 등 자본재 생산 과정에서 발생하는 온실가스 배출량
B6: - 비용 처리된 일반 소모품, 수리비, 용역비 등은 C1 구매품 및 서비스에 작성
B9: 작성 기준
B10: 1) 온실가스 산정 식: Σ(자본재 취득금액 × 자본재별 배출계수)
B11: - 배출계수는 US EPA Supply Chain Greenhouse Gas Emission Factors v1.3 등 지출기반 배출계수 활용
B12: 2) 취득금액은 회계상 자산 취득가액 기준으로 작성
B13: 3) 자산분류는 최종 배출계수 매핑 분류로 사용하므로 가장 가까운 항목을 선택
B15: ※ 사용 기준: 월별 자료가 있으면 1월~12월 칸에 입력하고, 연간 총량만 있으면 연간 입력 칸에 입력합니다. 동일 행에서 연간과 월별을 중복 입력하지 마세요.
B16: ※ 주황색으로 표시된 필수 입력칸은 반드시 작성해야 합니다.
B17: ※ 회색으로 표시된 입력란(배출계수, 배출량)은 자동으로 산출되므로 별도로 입력하지 않으셔도 됩니다.
B18: *국가 | C18: *사업장 | D18: *자산분류 | E18: *상세 자산명 | F18: 자산번호(선택) | G18: 계정과목(선택) | H18: 거래처명(선택) | I18: 연간 입력 | J18: 월별 취득금액 | V18: 비고(선택) | W18: 배출계수(kgCO2e/원) | X18: 배출량(tCO2e)
I19: 연간취득금액(원) | J19: 1월 | K19: 2월 | L19: 3월 | M19: 4월 | N19: 5월 | O19: 6월 | P19: 7월 | Q19: 8월 | R19: 9월 | S19: 10월 | T19: 11월 | U19: 12월
B20: 대한민국 | C20: 본사 | D20: IT장비 | E20: 노트북 | F20: FA-2025-001 | G20: 비품 | H20: 전자업체 | I20: =IF(SUM(J20:U20)=0,"",SUM(J20:U20)) | L20: 15000000 | V20: 업무용 노트북
I21: =IF(SUM(J21:U21)=0,"",SUM(J21:U21))
I22: =IF(SUM(J22:U22)=0,"",SUM(J22:U22))
I23: =IF(SUM(J23:U23)=0,"",SUM(J23:U23))
I24: =IF(SUM(J24:U24)=0,"",SUM(J24:U24))
I25: =IF(SUM(J25:U25)=0,"",SUM(J25:U25))
I26: =IF(SUM(J26:U26)=0,"",SUM(J26:U26))
I27: =IF(SUM(J27:U27)=0,"",SUM(J27:U27))
I28: =IF(SUM(J28:U28)=0,"",SUM(J28:U28))
I29: =IF(SUM(J29:U29)=0,"",SUM(J29:U29))
I30: =IF(SUM(J30:U30)=0,"",SUM(J30:U30))
I31: =IF(SUM(J31:U31)=0,"",SUM(J31:U31))
I32: =IF(SUM(J32:U32)=0,"",SUM(J32:U32))
... I55: =IF(SUM(J55:U55)=0,"",SUM(J55:U55))

Sheet C3_연료에너지
B2: C3. 연료 및 에너지 관련 활동
B4: 카테고리 정의
B5: - Scope 1, Scope 2에 포함되지 않은 연료 및 에너지의 업스트림 배출량과 송전·배전 손실에서 발생하는 온실가스 배출량
B6: - 직접 연소 배출량 또는 전력 사용 배출량 자체가 아니라 연료 생산·운송 및 전력 손실 등 간접 배출량에 해당
B9: 작성 기준
B10: 1) 온실가스 산정 식: Σ(연료/에너지 사용량 × 연료/에너지별 업스트림 또는 손실 배출계수)
B11: - 온실가스 배출계수는 환경부-환경성적표지(EPD) 평가계수, 국립환경과학원_Scope3 가이드라인를 활용
B12: 2) 원지출금액이 아니라 실제 사용량을 기준으로 작성
B13: 3) 연료/에너지명과 단위는 실제 사용한 항목 기준으로 선택
B14: 4) 동일한 연료라도 사업장, 단위, 사용 목적이 다르면 행을 나누어 작성
B16: ※ 사용 기준: 월별 자료가 있으면 1월~12월 칸에 입력하고, 연간 총량만 있으면 연간 입력 칸에 입력합니다. 동일 행에서 연간과 월별을 중복 입력하지 마세요.
B17: ※ 주황색으로 표시된 필수 입력칸은 반드시 작성해야 합니다.
B18: ※ 회색으로 표시된 입력란(배출계수, 배출량)은 자동으로 산출되므로 별도로 입력하지 않으셔도 됩니다.
B19: *국가 | C19: *사업장 | D19: *연료/에너지명 | E19: *단위 | F19: 연간 입력 | G19: 월별 사용량 | S19: 비고(선택) | T19: 배출계수(tCO2e/단위) | U19: 배출량(tCO2e)
F20: 연간사용량 | G20: 1월 | H20: 2월 | I20: 3월 | J20: 4월 | K20: 5월 | L20: 6월 | M20: 7월 | N20: 8월 | O20: 9월 | P20: 10월 | Q20: 11월 | R20: 12월
B21: 대한민국 | C21: 본사 | D21: 전력 | E21: kWh | F21: =IF(SUM(G21:R21)=0,"",SUM(G21:R21)) | G21: 10000 | H21: 10000 | I21: 10000 | J21: 10000 | K21: 10000 | L21: 10000 | M21: 10000 | N21: 10000 | O21: 10000 | P21: 10000 | Q21: 10000 | R21: 10000 | S21: 전력 사용량
F22: =IF(SUM(G22:R22)=0,"",SUM(G22:R22))
F23: =IF(SUM(G23:R23)=0,"",SUM(G23:R23))
F24: =IF(SUM(G24:R24)=0,"",SUM(G24:R24))
F25: =IF(SUM(G25:R25)=0,"",SUM(G25:R25))
F26: =IF(SUM(G26:R26)=0,"",SUM(G26:R26))
F27: =IF(SUM(G27:R27)=0,"",SUM(G27:R27))
F28: =IF(SUM(G28:R28)=0,"",SUM(G28:R28))
F29: =IF(SUM(G29:R29)=0,"",SUM(G29:R29))
F30: =IF(SUM(G30:R30)=0,"",SUM(G30:R30))
F31: =IF(SUM(G31:R31)=0,"",SUM(G31:R31))
F32: =IF(SUM(G32:R32)=0,"",SUM(G32:R32))
F33: =IF(SUM(G33:R33)=0,"",SUM(G33:R33))
... F56: =IF(SUM(G56:R56)=0,"",SUM(G56:R56))

Sheet C4-1_운송거리
B2: C4. 업스트림 운송·배송 1안. 출발지·도착지 기반
B4: 카테고리 정의
B5: - 보고년도에 회사가 구매한 원재료, 제품, 자재 등의 운송·배송 과정에서 발생하는 온실가스 배출량
B6: - 출발지와 도착지 또는 운송거리를 알고 있는 경우 작성
B9: 작성 기준
B10: 1) 온실가스 산정 식: Σ(화물중량 × 운송거리 × 운송수단별 배출계수)
B11: - 온실가스 배출계수는 환경부-환경성적표지(EPD) 평가계수를 활용
B12: 2) 운송수단은 도로, 해상, 항공, 철도 중 실제 주요 운송수단을 선택
B13: 3) 운송수단을 모르는 경우 출발지·도착지를 기준으로 AI가 운송수단 추정
B14: 4) 운송거리를 모르는 경우 출발지·도착지를 기준으로 AI가 거리 추정
B16: ※ 사용 기준: 월별 자료가 있으면 1월~12월 칸에 입력하고, 연간 총량만 있으면 연간 입력 칸에 입력합니다. 동일 행에서 연간과 월별을 중복 입력하지 마세요.
B17: ※ 주황색으로 표시된 필수 입력칸은 반드시 작성해야 합니다.
B18: ※ 회색으로 표시된 입력란(배출계수, 배출량)은 자동으로 산출되므로 별도로 입력하지 않으셔도 됩니다.
B19: *국가 | C19: *사업장 | D19: *운송수단(선택) | E19: *자재명/품목명 | F19: *중량단위 | G19: *출도착지 | I19: 운송거리(km)(선택) | J19: 연간 입력 | K19: 월별 운송량 | W19: 비고(선택) | X19: 배출계수(tCO2e/ton-km) | Y19: 배출량(tCO2e)
G20: *출발지 | H20: *도착지 | J20: 연간운송량 | K20: 1월 | L20: 2월 | M20: 3월 | N20: 4월 | O20: 5월 | P20: 6월 | Q20: 7월 | R20: 8월 | S20: 9월 | T20: 10월 | U20: 11월 | V20: 12월
B21: 대한민국 | C21: 평택공장 | D21: 도로 운송 (일반화물트럭) | E21: 원재료 A | F21: ton | G21: 부산항 | H21: 평택공장 | I21: 380 | J21: =IF(SUM(K21:V21)=0,"",SUM(K21:V21)) | K21: 20 | L21: 20 | M21: 20 | N21: 20 | O21: 20 | P21: 20 | Q21: 20 | R21: 20 | S21: 20 | T21: 20 | U21: 20 | V21: 20 | W21: 입고 물류
J22: =IF(SUM(K22:V22)=0,"",SUM(K22:V22))
J23: =IF(SUM(K23:V23)=0,"",SUM(K23:V23))
J24: =IF(SUM(K24:V24)=0,"",SUM(K24:V24))
J25: =IF(SUM(K25:V25)=0,"",SUM(K25:V25))
J26: =IF(SUM(K26:V26)=0,"",SUM(K26:V26))
J27: =IF(SUM(K27:V27)=0,"",SUM(K27:V27))
J28: =IF(SUM(K28:V28)=0,"",SUM(K28:V28))
J29: =IF(SUM(K29:V29)=0,"",SUM(K29:V29))
J30: =IF(SUM(K30:V30)=0,"",SUM(K30:V30))
J31: =IF(SUM(K31:V31)=0,"",SUM(K31:V31))
J32: =IF(SUM(K32:V32)=0,"",SUM(K32:V32))
J33: =IF(SUM(K33:V33)=0,"",SUM(K33:V33))
... J56: =IF(SUM(K56:V56)=0,"",SUM(K56:V56))

Sheet C4-2_운송금액
B2: C4. 업스트림 운송·배송 2안. 운송금액 기반
B4: 카테고리 정의
B5: - 보고년도에 회사가 구매한 원재료, 제품, 자재 등의 운송·배송 비용을 기준으로 산정하는 온실가스 배출량
B6: - 출발지, 도착지, 운송거리, 화물중량을 알 수 없고 운송비 또는 물류비만 확인 가능한 경우 작성
B9: 작성 기준
B10: 1) 온실가스 산정 식: Σ(운송지출금액 × 운송/물류 지출기반 배출계수)
B11: - 배출계수는 US EPA Supply Chain Greenhouse Gas Emission Factors v1.3 등 지출기반 배출계수 활용
B12: 2) 운송수단은 도로, 해상, 항공, 철도 중 실제 주요 운송수단을 선택
B13: 3) 운송수단을 모르는 경우 출발지·도착지를 기준으로 AI가 운송수단 추정
B14: 4) 운송금액은 실제 운송비, 물류비, 배송비, 포워딩 비용 등을 기준으로 작성
B15: 5) 출발지·도착지와 화물중량을 알고 있는 경우 C4-1 시트에 작성
B17: ※ 사용 기준: 월별 자료가 있으면 1월~12월 칸에 입력하고, 연간 총량만 있으면 연간 입력 칸에 입력합니다. 동일 행에서 연간과 월별을 중복 입력하지 마세요.
... B19: ※ 회색으로 표시된 입력란(배출계수, 배출량)은 자동으로 산출되므로 별도로 입력하지 않으셔도 됩니다.
B20: *국가 | C20: *사업장 | D20: 운송수단(선택) | E20: *자재명/품목명 | F20: 거래처명(선택) | G20: 연간 입력 | H20: 월별 운송금액 | T20: 비고(선택) | U20: 배출계수(kgCO2e/원) | V20: 배출량(tCO2e)
G21: 연간운송금액(원) | H21: 1월 | I21: 2월 | J21: 3월 | K21: 4월 | L21: 5월 | M21: 6월 | N21: 7월 | O21: 8월 | P21: 9월 | Q21: 10월 | R21: 11월 | S21: 12월
B22: 대한민국 | C22: 평택공장 | D22: 화물트럭 운송 | E22: 원재료 A | F22: 물류업체 | G22: =IF(SUM(H22:S22)=0,"",SUM(H22:S22)) | H22: 1000000 | I22: 1000000 | J22: 1000000 | K22: 1000000 | L22: 1000000 | M22: 1000000 | N22: 1000000 | O22: 1000000 | P22: 1000000 | Q22: 1000000 | R22: 1000000 | S22: 1000000 | T22: 운송비 기준
G23: =IF(SUM(H23:S23)=0,"",SUM(H23:S23))
G24: =IF(SUM(H24:S24)=0,"",SUM(H24:S24))
G25: =IF(SUM(H25:S25)=0,"",SUM(H25:S25))
G26: =IF(SUM(H26:S26)=0,"",SUM(H26:S26))
G27: =IF(SUM(H27:S27)=0,"",SUM(H27:S27))
G28: =IF(SUM(H28:S28)=0,"",SUM(H28:S28))
G29: =IF(SUM(H29:S29)=0,"",SUM(H29:S29))
G30: =IF(SUM(H30:S30)=0,"",SUM(H30:S30))
G31: =IF(SUM(H31:S31)=0,"",SUM(H31:S31))
G32: =IF(SUM(H32:S32)=0,"",SUM(H32:S32))
G33: =IF(SUM(H33:S33)=0,"",SUM(H33:S33))
G34: =IF(SUM(H34:S34)=0,"",SUM(H34:S34))
... G57: =IF(SUM(H57:S57)=0,"",SUM(H57:S57))

Sheet C5_사업장폐기물
B2: C5. 사업장 발생 폐기물
B4: 카테고리 정의
B5: - 보고년도에 운영 과정에서 발생한 폐기물의 처리·반매립·소각 시 발생한 온실가스 배출량
B6: - 본사, 지부, 복지시설 운영 과정의 일반 폐기물, 음식물 쓰레기 등도 포함
B9: 작성 기준
B10: 1) 온실가스 산정 식: Σ(폐기물 발생량 × 처리방법별 배출계수)
B11: - 배출계수는 환경부 환경성적표지(EPD) 등 폐기물 처리 배출계수 활용
B12: 2) 상세 폐기물명은 실제 처리업체 자료, 올바로시스템 명칭 기준으로 작성
B13: 3) 동일한 폐기물이라도 처리방법이 다르면 행을 나누어 작성
B14: *적용 기업명 | C14: =기업정보!$C$7
B15: ※ 이 값은 '기업정보' 시트에서 선택한 적용 기업명이 자동으로 반영된 것입니다. 상세 폐기물명(E열) 입력 시 폐기물 종류(D열)가 '회사별_폐기물매핑' 매핑표를 기준으로 자동 매칭됩니다.
B16: ※ 사용 기준: 월별 자료가 있으면 1월~12월 칸에 입력하고, 연간 총량만 있으면 연간 입력 칸에 입력합니다. 동일 행에서 연간과 월별을 중복 입력하지 마세요.
B17: ※ 주황색으로 표시된 필수 입력칸은 반드시 작성해야 합니다.
B18: ※ 회색으로 표시된 입력란(배출계수, 배출량)은 자동으로 산출되므로 별도로 입력하지 않으셔도 됩니다.
B19: *국가 | C19: *사업장 | D19: *폐기물 종류 | E19: 상세 폐기물명(선택) | F19: *단위 | G19: *처리방법 | H19: 연간 입력 | I19: 월별 처리량 | U19: 비고(선택) | V19: 배출계수(tCO2e/단위) | W19: 배출량(tCO2e)
H20: 연간처리량 | I20: 1월 | J20: 2월 | K20: 3월 | L20: 4월 | M20: 5월 | N20: 6월 | O20: 7월 | P20: 8월 | Q20: 9월 | R20: 10월 | S20: 11월 | T20: 12월
B21: 대한민국 | C21: 본사 | D21: 폐지류 | E21: 골판지 박스 | F21: kg | G21: 재활용 | H21: =IF(SUM(I21:T21)=0,"",SUM(I21:T21)) | I21: 10 | J21: 10 | K21: 10 | L21: 10 | M21: 10 | N21: 10 | O21: 10 | P21: 10 | Q21: 10 | R21: 10 | S21: 10 | T21: 10 | U21: 처리업체 자료 기준
D22: =IFERROR(INDEX(회사별_폐기물매핑!$C$2:$C$1000,MATCH(1,INDEX(($C$14=회사별_폐기물매핑!$A$2:$A$1000)*($E22=회사별_폐기물매핑!$B$2:$B$1000),0),0)),"") | E22: 일반쓰레기 | H22: =IF(SUM(I22:T22)=0,"",SUM(I22:T22))
D23: =IFERROR(INDEX(회사별_폐기물매핑!$C$2:$C$1000,MATCH(1,INDEX(($C$14=회사별_폐기물매핑!$A$2:$A$1000)*($E23=회사별_폐기물매핑!$B$2:$B$1000),0),0)),"") | E23: 폐아스발트 | H23: =IF(SUM(I23:T23)=0,"",SUM(I23:T23))
D24: =IFERROR(INDEX(회사별_폐기물매핑!$C$2:$C$1000,MATCH(1,INDEX(($C$14=회사별_폐기물매핑!$A$2:$A$1000)*($E24=회사별_폐기물매핑!$B$2:$B$1000),0),0)),"") | H24: =IF(SUM(I24:T24)=0,"",SUM(I24:T24))
D25: =IFERROR(INDEX(회사별_폐기물매핑!$C$2:$C$1000,MATCH(1,INDEX(($C$14=회사별_폐기물매핑!$A$2:$A$1000)*($E25=회사별_폐기물매핑!$B$2:$B$1000),0),0)),"") | H25: =IF(SUM(I25:T25)=0,"",SUM(I25:T25))
D26: =IFERROR(INDEX(회사별_폐기물매핑!$C$2:$C$1000,MATCH(1,INDEX(($C$14=회사별_폐기물매핑!$A$2:$A$1000)*($E26=회사별_폐기물매핑!$B$2:$B$1000),0),0)),"") | H26: =IF(SUM(I26:T26)=0,"",SUM(I26:T26))
D27: =IFERROR(INDEX(회사별_폐기물매핑!$C$2:$C$1000,MATCH(1,INDEX(($C$14=회사별_폐기물매핑!$A$2:$A$1000)*($E27=회사별_폐기물매핑!$B$2:$B$1000),0),0)),"") | H27: =IF(SUM(I27:T27)=0,"",SUM(I27:T27))
D28: =IFERROR(INDEX(회사별_폐기물매핑!$C$2:$C$1000,MATCH(1,INDEX(($C$14=회사별_폐기물매핑!$A$2:$A$1000)*($E28=회사별_폐기물매핑!$B$2:$B$1000),0),0)),"") | H28: =IF(SUM(I28:T28)=0,"",SUM(I28:T28))
D29: =IFERROR(INDEX(회사별_폐기물매핑!$C$2:$C$1000,MATCH(1,INDEX(($C$14=회사별_폐기물매핑!$A$2:$A$1000)*($E29=회사별_폐기물매핑!$B$2:$B$1000),0),0)),"") | H29: =IF(SUM(I29:T29)=0,"",SUM(I29:T29))
D30: =IFERROR(INDEX(회사별_폐기물매핑!$C$2:$C$1000,MATCH(1,INDEX(($C$14=회사별_폐기물매핑!$A$2:$A$1000)*($E30=회사별_폐기물매핑!$B$2:$B$1000),0),0)),"") | H30: =IF(SUM(I30:T30)=0,"",SUM(I30:T30))
D31: =IFERROR(INDEX(회사별_폐기물매핑!$C$2:$C$1000,MATCH(1,INDEX(($C$14=회사별_폐기물매핑!$A$2:$A$1000)*($E31=회사별_폐기물매핑!$B$2:$B$1000),0),0)),"") | H31: =IF(SUM(I31:T31)=0,"",SUM(I31:T31))
D32: =IFERROR(INDEX(회사별_폐기물매핑!$C$2:$C$1000,MATCH(1,INDEX(($C$14=회사별_폐기물매핑!$A$2:$A$1000)*($E32=회사별_폐기물매핑!$B$2:$B$1000),0),0)),"") | H32: =IF(SUM(I32:T32)=0,"",SUM(I32:T32))
D33: =IFERROR(INDEX(회사별_폐기물매핑!$C$2:$C$1000,MATCH(1,INDEX(($C$14=회사별_폐기물매핑!$A$2:$A$1000)*($E33=회사별_폐기물매핑!$B$2:$B$1000),0),0)),"") | H33: =IF(SUM(I33:T33)=0,"",SUM(I33:T33))
D34: =IFERROR(INDEX(회사별_폐기물매핑!$C$2:$C$1000,MATCH(1,INDEX(($C$14=회사별_폐기물매핑!$A$2:$A$1000)*($E34=회사별_폐기물매핑!$B$2:$B$1000),0),0)),"") | H34: =IF(SUM(I34:T34)=0,"",SUM(I34:T34))
D35: =IFERROR(INDEX(회사별_폐기물매핑!$C$2:$C$1000,MATCH(1,INDEX(($C$14=회사별_폐기물매핑!$A$2:$A$1000)*($E35=회사별_폐기물매핑!$B$2:$B$1000),0),0)),"") | H35: =IF(SUM(I35:T35)=0,"",SUM(I35:T35))
... D221: =IFERROR(INDEX(회사별_폐기물매핑!$C$2:$C$1000,MATCH(1,INDEX(($C$14=회사별_폐기물매핑!$A$2:$A$1000)*($E221=회사별_폐기물매핑!$B$2:$B$1000),0),0)),"") | H221: =IF(SUM(I221:T221)=0,"",SUM(I221:T221))

Sheet C6-1_출장거리
B2: C6. 임직원 출장 1안. 이동거리 기반
B4: 카테고리 정의
B5: - 보고년도에 임직원 업무 출장 시 항공, 철도, 차량 등 교통수단 이용으로 발생한 온실가스 배출량
B6: - 출발지와 도착지 또는 이동거리를 알고 있는 출장에 적용
B9: 작성 기준
B10: 1) 온실가스 산정 식: Σ(왕복 이동거리 × 교통수단별 배출계수 × 인원수 × 이동횟수)
B11: - 온실가스 배출계수는 UK defra 평가계수를 활용 (*UK Government GHG Conversion Factor )
B12: 2) 편도거리나 출도착지 둘 중 하나는 반드시 작성(노란 박스) / 항공을 이용한 경우 출도착지는 도시명·주소 대신 공항명(예: 인천국제공항)으로 작성 권장 - 미기재 시 AI가 가까운 주요 공항으로 추정해 거리를 계산합니다(주소 기준으로 바로 계산하면 실제 항공 이동거리와 달라질 수 있음)
B13: 3) 숙박비와 교통비 지출금액만 아는 경우 C6-2 시트에 작성
B14: *적용 기업명 | C14: =기업정보!$C$7
B15: ※ '기업정보' 시트에서 선택한 적용 기업명이 자동 반영됩니다. 상세 교통수단명(Y열) 입력 시 *교통수단(D열)이 '회사별_교통수단매핑' 매핑표를 기준으로 자동 매칭됩니다.
B16: ※ 사용 기준: 월별 자료가 있으면 1월~12월 칸에 입력하고, 연간 총량만 있으면 연간 입력 칸에 입력합니다. 동일 행에서 연간과 월별을 중복 입력하지 마세요.
B17: ※ 주황색으로 표시된 필수 입력칸은 반드시 작성해야 합니다.
B18: ※ 회색으로 표시된 입력란(배출계수, 배출량)은 자동으로 산출되므로 별도로 입력하지 않으셔도 됩니다.
B19: *국가 | C19: *출장주체 | D19: *교통수단 | E19: *인원수 | F19: 출도착지 | I19: 연간 입력 | J19: 월별 이동횟수 | V19: 비고(선택) | W19: 배출계수(tCO2e/km) | X19: 배출량(tCO2e) | Y19: 상세 교통수단명(선택)
F20: 출발지 | G20: 도착지 | H20: 편도거리(km)(선택) | I20: 연간이동횟수 | J20: 1월 | K20: 2월 | L20: 3월 | M20: 4월 | N20: 5월 | O20: 6월 | P20: 7월 | Q20: 8월 | R20: 9월 | S20: 10월 | T20: 11월 | U20: 12월
B21: 대한민국 | C21: 본사 | D21: 철도/KTX/SRT | E21: 2 | F21: 서울역 | G21: 부산역 | H21: 325 | I21: =IF(SUM(J21:U21)=0,"",SUM(J21:U21)) | L21: 1 | P21: 1 | T21: 1
D22: 국내선 항공 | I22: =IF(SUM(J22:U22)=0,"",SUM(J22:U22))
D23: =IFERROR(INDEX(회사별_교통수단매핑!$C$2:$C$1000,MATCH(1,INDEX(($C$14=회사별_교통수단매핑!$A$2:$A$1000)*($Y23=회사별_교통수단매핑!$B$2:$B$1000),0),0)),"") | I23: =IF(SUM(J23:U23)=0,"",SUM(J23:U23))
D24: =IFERROR(INDEX(회사별_교통수단매핑!$C$2:$C$1000,MATCH(1,INDEX(($C$14=회사별_교통수단매핑!$A$2:$A$1000)*($Y24=회사별_교통수단매핑!$B$2:$B$1000),0),0)),"") | I24: =IF(SUM(J24:U24)=0,"",SUM(J24:U24))
D25: =IFERROR(INDEX(회사별_교통수단매핑!$C$2:$C$1000,MATCH(1,INDEX(($C$14=회사별_교통수단매핑!$A$2:$A$1000)*($Y25=회사별_교통수단매핑!$B$2:$B$1000),0),0)),"") | I25: =IF(SUM(J25:U25)=0,"",SUM(J25:U25))
D26: =IFERROR(INDEX(회사별_교통수단매핑!$C$2:$C$1000,MATCH(1,INDEX(($C$14=회사별_교통수단매핑!$A$2:$A$1000)*($Y26=회사별_교통수단매핑!$B$2:$B$1000),0),0)),"") | I26: =IF(SUM(J26:U26)=0,"",SUM(J26:U26))
D27: =IFERROR(INDEX(회사별_교통수단매핑!$C$2:$C$1000,MATCH(1,INDEX(($C$14=회사별_교통수단매핑!$A$2:$A$1000)*($Y27=회사별_교통수단매핑!$B$2:$B$1000),0),0)),"") | I27: =IF(SUM(J27:U27)=0,"",SUM(J27:U27))
D28: =IFERROR(INDEX(회사별_교통수단매핑!$C$2:$C$1000,MATCH(1,INDEX(($C$14=회사별_교통수단매핑!$A$2:$A$1000)*($Y28=회사별_교통수단매핑!$B$2:$B$1000),0),0)),"") | I28: =IF(SUM(J28:U28)=0,"",SUM(J28:U28))
D29: =IFERROR(INDEX(회사별_교통수단매핑!$C$2:$C$1000,MATCH(1,INDEX(($C$14=회사별_교통수단매핑!$A$2:$A$1000)*($Y29=회사별_교통수단매핑!$B$2:$B$1000),0),0)),"") | I29: =IF(SUM(J29:U29)=0,"",SUM(J29:U29))
D30: =IFERROR(INDEX(회사별_교통수단매핑!$C$2:$C$1000,MATCH(1,INDEX(($C$14=회사별_교통수단매핑!$A$2:$A$1000)*($Y30=회사별_교통수단매핑!$B$2:$B$1000),0),0)),"") | I30: =IF(SUM(J30:U30)=0,"",SUM(J30:U30))
D31: =IFERROR(INDEX(회사별_교통수단매핑!$C$2:$C$1000,MATCH(1,INDEX(($C$14=회사별_교통수단매핑!$A$2:$A$1000)*($Y31=회사별_교통수단매핑!$B$2:$B$1000),0),0)),"") | I31: =IF(SUM(J31:U31)=0,"",SUM(J31:U31))
D32: =IFERROR(INDEX(회사별_교통수단매핑!$C$2:$C$1000,MATCH(1,INDEX(($C$14=회사별_교통수단매핑!$A$2:$A$1000)*($Y32=회사별_교통수단매핑!$B$2:$B$1000),0),0)),"") | I32: =IF(SUM(J32:U32)=0,"",SUM(J32:U32))
D33: =IFERROR(INDEX(회사별_교통수단매핑!$C$2:$C$1000,MATCH(1,INDEX(($C$14=회사별_교통수단매핑!$A$2:$A$1000)*($Y33=회사별_교통수단매핑!$B$2:$B$1000),0),0)),"") | I33: =IF(SUM(J33:U33)=0,"",SUM(J33:U33))
D34: =IFERROR(INDEX(회사별_교통수단매핑!$C$2:$C$1000,MATCH(1,INDEX(($C$14=회사별_교통수단매핑!$A$2:$A$1000)*($Y34=회사별_교통수단매핑!$B$2:$B$1000),0),0)),"") | I34: =IF(SUM(J34:U34)=0,"",SUM(J34:U34))
... D221: =IFERROR(INDEX(회사별_교통수단매핑!$C$2:$C$1000,MATCH(1,INDEX(($C$14=회사별_교통수단매핑!$A$2:$A$1000)*($Y221=회사별_교통수단매핑!$B$2:$B$1000),0),0)),"") | I221: =IF(SUM(J221:U221)=0,"",SUM(J221:U221))

Sheet C6-2_출장비
B2: C6. 임직원 출장 2안. 출장비 기반
B4: 카테고리 정의
B5: - 보고년도에 임직원 업무 출장 시 지출한 금액을 경제적 배출계수로 적용하여 산정하는 온실가스 배출량
B6: - 출발지, 도착지, 이동거리 정보를 알 수 없고 출장비만 확인 가능한 경우 작성
B9: 작성 기준
B10: 1) 온실가스 산정 식: Σ(출장지출금액 × 지출기반 배출계수)
B11: - 온실가스 배출계수는 US EPA Emission Factor 활용 (*US EPA Supply Chain Greenhouse Gas Emission Factors v1.3 by NAICS-6)
B12: 2) 출장항목은 항공, 철도, 택시, 렌터카, 숙박 등으로 작성
B13: 3) 거리 기반 정보가 있는 경우 C6-1 시트에 작성
B16: ※ 사용 기준: 월별 자료가 있으면 1월~12월 칸에 입력하고, 연간 총량만 있으면 연간 입력 칸에 입력합니다. 동일 행에서 연간과 월별을 중복 입력하지 마세요.
B17: ※ 주황색으로 표시된 필수 입력칸은 반드시 작성해야 합니다.
B18: ※ 회색으로 표시된 입력란(배출계수, 배출량)은 자동으로 산출되므로 별도로 입력하지 않으셔도 됩니다.
B19: *국가 | C19: *출장주체 | F19: 연간 입력 | G19: 월별 지출금액 | S19: 비고(선택) | T19: 배출계수(kgCO2e/원) | U19: 배출량(tCO2e)
D20: *출장항목 | E20: *인원수 | F20: 연간지출금액(원) | G20: 1월 | H20: 2월 | I20: 3월 | J20: 4월 | K20: 5월 | L20: 6월 | M20: 7월 | N20: 8월 | O20: 9월 | P20: 10월 | Q20: 11월 | R20: 12월
B21: 영국 | C21: 강남지사 | D21: 항공권(여객·전세) | E21: 3 | F21: =IF(SUM(G21:R21)=0,"",SUM(G21:R21)) | G21: 360000 | H21: 360000 | I21: 360000 | J21: 360000 | K21: 360000 | L21: 360000 | M21: 360000 | N21: 360000 | O21: 360000 | P21: 360000 | Q21: 360000 | R21: 360000 | S21: 해외 출장 항공권
F22: =IF(SUM(G22:R22)=0,"",SUM(G22:R22))
F23: =IF(SUM(G23:R23)=0,"",SUM(G23:R23))
F24: =IF(SUM(G24:R24)=0,"",SUM(G24:R24))
F25: =IF(SUM(G25:R25)=0,"",SUM(G25:R25))
F26: =IF(SUM(G26:R26)=0,"",SUM(G26:R26))
F27: =IF(SUM(G27:R27)=0,"",SUM(G27:R27))
F28: =IF(SUM(G28:R28)=0,"",SUM(G28:R28))
F29: =IF(SUM(G29:R29)=0,"",SUM(G29:R29))
F30: =IF(SUM(G30:R30)=0,"",SUM(G30:R30))
F31: =IF(SUM(G31:R31)=0,"",SUM(G31:R31))
F32: =IF(SUM(G32:R32)=0,"",SUM(G32:R32))
F33: =IF(SUM(G33:R33)=0,"",SUM(G33:R33))
... F56: =IF(SUM(G56:R56)=0,"",SUM(G56:R56))

Sheet C7_임직원통근
B2: C7. 임직원 통근
B4: 카테고리 정의
B5: - 보고년도에 직원이 출퇴근 과정에서 발생하는 온실가스 배출량
B6: - 보유하지 않거나 운영하지 않는 교통수단을 이용한 내역만 해당
B9: 작성 기준
B10: 1) 온실가스 산정 식: Σ(왕복 이동거리 × 연간 근무일수 × 교통수단별 배출계수 × 인원수)
B11: - 온실가스 배출계수는 UK defra 평가계수를 활용 (*UK Government GHG Conversion Factor )
B12: 2) 편도거리나 출도착지 둘 중 하나는 반드시 작성(노란 박스) / 항공을 이용한 경우 출도착지는 도시명·주소 대신 공항명(예: 인천국제공항)으로 작성 권장 - 미기재 시 AI가 가까운 주요 공항으로 추정해 거리를 계산합니다(주소 기준으로 바로 계산하면 실제 항공 이동거리와 달라질 수 있음)
B13: - 출발지는 거주지 또는 주요 출발지, 도착지는 회사 주소로 작성
B14: 3) 근무일수는 연도별 실제 근무일수(365일 - 공제일 수)로 집계 : 공제일 (토/일요일, 공휴일, 대체공휴일, 회사지정휴일 등) 평균적으로 245일 활용
B15: *적용 기업명 | C15: =기업정보!$C$7
B16: ※ '기업정보' 시트에서 선택한 적용 기업명이 자동 반영됩니다. 상세 교통수단명(Y열) 입력 시 *교통수단(D열)이 '회사별_교통수단매핑' 매핑표를 기준으로 자동 매칭됩니다.
B17: ※ 사용 기준: 월별 자료가 있으면 1월~12월 칸에 입력하고, 연간 총량만 있으면 연간 입력 칸에 입력합니다. 동일 행에서 연간과 월별을 중복 입력하지 마세요.
B18: ※ 주황색으로 표시된 필수 입력칸은 반드시 작성해야 합니다.
B19: ※ 회색으로 표시된 입력란(배출계수, 배출량)은 자동으로 산출되므로 별도로 입력하지 않으셔도 됩니다.
B20: *국가 | C20: *사업장 | D20: *교통수단 | E20: *인원수 | F20: 출도착지 | H20: 편도거리(km)(선택) | I20: 연간 입력 | J20: 월별 근무일수 | V20: 비고(선택) | W20: 배출계수(tCO2e/km) | X20: 배출량(tCO2e) | Y20: 상세 교통수단명(선택)
F21: 출발지 | G21: 도착지 | I21: 연간근무일수 | J21: 1월 | K21: 2월 | L21: 3월 | M21: 4월 | N21: 5월 | O21: 6월 | P21: 7월 | Q21: 8월 | R21: 9월 | S21: 10월 | T21: 11월 | U21: 12월
B22: 대한민국 | C22: 본사 | D22: 지하철/도시철도 | E22: 35 | F22: 제주시 서귀포시 강정동 | G22: 제주시 본사 | I22: =IF(SUM(J22:U22)=0,"",SUM(J22:U22)) | V22: 임직원 통근
D23: =IFERROR(INDEX(회사별_교통수단매핑!$C$2:$C$1000,MATCH(1,INDEX(($C$15=회사별_교통수단매핑!$A$2:$A$1000)*($Y23=회사별_교통수단매핑!$B$2:$B$1000),0),0)),"") | I23: =IF(SUM(J23:U23)=0,"",SUM(J23:U23))
D24: =IFERROR(INDEX(회사별_교통수단매핑!$C$2:$C$1000,MATCH(1,INDEX(($C$15=회사별_교통수단매핑!$A$2:$A$1000)*($Y24=회사별_교통수단매핑!$B$2:$B$1000),0),0)),"") | I24: =IF(SUM(J24:U24)=0,"",SUM(J24:U24))
D25: =IFERROR(INDEX(회사별_교통수단매핑!$C$2:$C$1000,MATCH(1,INDEX(($C$15=회사별_교통수단매핑!$A$2:$A$1000)*($Y25=회사별_교통수단매핑!$B$2:$B$1000),0),0)),"") | I25: =IF(SUM(J25:U25)=0,"",SUM(J25:U25))
D26: =IFERROR(INDEX(회사별_교통수단매핑!$C$2:$C$1000,MATCH(1,INDEX(($C$15=회사별_교통수단매핑!$A$2:$A$1000)*($Y26=회사별_교통수단매핑!$B$2:$B$1000),0),0)),"") | I26: =IF(SUM(J26:U26)=0,"",SUM(J26:U26))
D27: =IFERROR(INDEX(회사별_교통수단매핑!$C$2:$C$1000,MATCH(1,INDEX(($C$15=회사별_교통수단매핑!$A$2:$A$1000)*($Y27=회사별_교통수단매핑!$B$2:$B$1000),0),0)),"") | I27: =IF(SUM(J27:U27)=0,"",SUM(J27:U27))
D28: =IFERROR(INDEX(회사별_교통수단매핑!$C$2:$C$1000,MATCH(1,INDEX(($C$15=회사별_교통수단매핑!$A$2:$A$1000)*($Y28=회사별_교통수단매핑!$B$2:$B$1000),0),0)),"") | I28: =IF(SUM(J28:U28)=0,"",SUM(J28:U28))
D29: =IFERROR(INDEX(회사별_교통수단매핑!$C$2:$C$1000,MATCH(1,INDEX(($C$15=회사별_교통수단매핑!$A$2:$A$1000)*($Y29=회사별_교통수단매핑!$B$2:$B$1000),0),0)),"") | I29: =IF(SUM(J29:U29)=0,"",SUM(J29:U29))
D30: =IFERROR(INDEX(회사별_교통수단매핑!$C$2:$C$1000,MATCH(1,INDEX(($C$15=회사별_교통수단매핑!$A$2:$A$1000)*($Y30=회사별_교통수단매핑!$B$2:$B$1000),0),0)),"") | I30: =IF(SUM(J30:U30)=0,"",SUM(J30:U30))
D31: =IFERROR(INDEX(회사별_교통수단매핑!$C$2:$C$1000,MATCH(1,INDEX(($C$15=회사별_교통수단매핑!$A$2:$A$1000)*($Y31=회사별_교통수단매핑!$B$2:$B$1000),0),0)),"") | I31: =IF(SUM(J31:U31)=0,"",SUM(J31:U31))
D32: =IFERROR(INDEX(회사별_교통수단매핑!$C$2:$C$1000,MATCH(1,INDEX(($C$15=회사별_교통수단매핑!$A$2:$A$1000)*($Y32=회사별_교통수단매핑!$B$2:$B$1000),0),0)),"") | I32: =IF(SUM(J32:U32)=0,"",SUM(J32:U32))
D33: =IFERROR(INDEX(회사별_교통수단매핑!$C$2:$C$1000,MATCH(1,INDEX(($C$15=회사별_교통수단매핑!$A$2:$A$1000)*($Y33=회사별_교통수단매핑!$B$2:$B$1000),0),0)),"") | I33: =IF(SUM(J33:U33)=0,"",SUM(J33:U33))
D34: =IFERROR(INDEX(회사별_교통수단매핑!$C$2:$C$1000,MATCH(1,INDEX(($C$15=회사별_교통수단매핑!$A$2:$A$1000)*($Y34=회사별_교통수단매핑!$B$2:$B$1000),0),0)),"") | I34: =IF(SUM(J34:U34)=0,"",SUM(J34:U34))
... D222: =IFERROR(INDEX(회사별_교통수단매핑!$C$2:$C$1000,MATCH(1,INDEX(($C$15=회사별_교통수단매핑!$A$2:$A$1000)*($Y222=회사별_교통수단매핑!$B$2:$B$1000),0),0)),"") | I222: =IF(SUM(J222:U222)=0,"",SUM(J222:U222))

Sheet C8-1_에너지사용량 아는 경우
B2: C8. 업스트림 임차자산 1안. 에너지 사용량을 알고 있을 때
B4: 카테고리 정의
B5: - 보고년도에 회사가 임차자산으로 사용하는 자산에서 발생하는 온실가스 배출량
B6: - 해당 자산의 실제 에너지 사용량을 알고 있을 때 작성
B9: 작성 기준
B10: 1) 온실가스 산정 식: Σ(에너지 사용량 × 에너지원별 배출계수)
B11: - 온실가스 배출 계수는 국가 승인 고유 배출계수(국내)와 IPCC 가이드라인 배출계수(해외), 환경부_환경성적표지(EPD) 배출계수를 활용
B12: 2) 원자료는 반드시 작성하고 데이터는 연간 또는 월별 작성 가능
B13: 3) 한 자산에서 1개 이상 에너지원을 사용하는 경우 에너지원별로 행을 나누어 작성
B16: ※ 사용 기준: 월별 자료가 있으면 1월~12월 칸에 입력하고, 연간 총량만 있으면 연간 입력 칸에 입력합니다. 동일 행에서 연간과 월별을 중복 입력하지 마세요.
B17: ※ 주황색으로 표시된 필수 입력칸은 반드시 작성해야 합니다.
B18: ※ 회색으로 표시된 입력란(배출계수, 배출량)은 자동으로 산출되므로 별도로 입력하지 않으셔도 됩니다.
B19: *국가 | C19: *임차자산명 | D19: *에너지종류 | F19: 연간 입력 | G19: 월별 사용량 | S19: 비고(선택) | T19: 배출계수(tCO2e/단위) | U19: 배출량(tCO2e)
E20: *단위 | F20: *연간사용량 | G20: 1월 | H20: 2월 | I20: 3월 | J20: 4월 | K20: 5월 | L20: 6월 | M20: 7월 | N20: 8월 | O20: 9월 | P20: 10월 | Q20: 11월 | R20: 12월
B21: 대한민국 | C21: 임차자산 A | D21: 전력 | E21: kWh | F21: =IF(SUM(G21:R21)=0,"",SUM(G21:R21)) | G21: 10000 | H21: 10000 | I21: 10000 | J21: 10000 | K21: 10000 | L21: 10000 | M21: 10000 | N21: 10000 | O21: 10000 | P21: 10000 | Q21: 10000 | R21: 10000 | S21: 전력 사용량
F22: =IF(SUM(G22:R22)=0,"",SUM(G22:R22))
F23: =IF(SUM(G23:R23)=0,"",SUM(G23:R23))
F24: =IF(SUM(G24:R24)=0,"",SUM(G24:R24))
F25: =IF(SUM(G25:R25)=0,"",SUM(G25:R25))
F26: =IF(SUM(G26:R26)=0,"",SUM(G26:R26))
F27: =IF(SUM(G27:R27)=0,"",SUM(G27:R27))
F28: =IF(SUM(G28:R28)=0,"",SUM(G28:R28))
F29: =IF(SUM(G29:R29)=0,"",SUM(G29:R29))
F30: =IF(SUM(G30:R30)=0,"",SUM(G30:R30))
F31: =IF(SUM(G31:R31)=0,"",SUM(G31:R31))
F32: =IF(SUM(G32:R32)=0,"",SUM(G32:R32))
F33: =IF(SUM(G33:R33)=0,"",SUM(G33:R33))
... F56: =IF(SUM(G56:R56)=0,"",SUM(G56:R56))

Sheet C8-2_면적
B2: C8. 업스트림 임차자산 2안. 건물전체 에너지사용량만 알고 있을 때
B4: 카테고리 정의
B5: - 회사가 사용하는 임차자산의 에너지 사용량을 직접 알 수 없는 경우 산정
B6: - 건물 전체 에너지 사용량은 알고 있으나 면적 기준으로 배분해야 할 때 작성
B9: 작성 기준
B10: 1) 온실가스 산정 식: Σ((사용 면적 / 건물전체 면적) × 건물전체 에너지 사용량 × 에너지원별 배출계수)
B11: - 온실가스 배출 계수는 국가 승인 고유 배출계수(국내)와 IPCC 가이드라인 배출계수(해외), 환경부_환경성적표지(EPD) 배출계수를 활용
B12: 2) 건물전체 면적과 사용 면적은 반드시 작성
B13: 3) 원자료는 반드시 작성하고 데이터는 연간 또는 월별 작성 가능
B16: ※ 사용 기준: 월별 자료가 있으면 1월~12월 칸에 입력하고, 연간 총량만 있으면 연간 입력 칸에 입력합니다. 동일 행에서 연간과 월별을 중복 입력하지 마세요.
B17: ※ 주황색으로 표시된 필수 입력칸은 반드시 작성해야 합니다.
B18: ※ 회색으로 표시된 입력란(배출계수, 배출량)은 자동으로 산출되므로 별도로 입력하지 않으셔도 됩니다.
B19: *국가 | C19: *임차자산명 | D19: *건물전체 면적 | E19: *사용 면적 | F19: *에너지종류 | G19: *단위 | H19: 연간 입력 | I19: 건물전체 월별사용량 | U19: 비고(선택) | V19: 배출계수(tCO2e/단위) | W19: 배출량(tCO2e)
H20: *건물전체 연간사용량 | I20: 1월 | J20: 2월 | K20: 3월 | L20: 4월 | M20: 5월 | N20: 6월 | O20: 7월 | P20: 8월 | Q20: 9월 | R20: 10월 | S20: 11월 | T20: 12월
B21: 대한민국 | C21: 임차자산 B | D21: 13908 | E21: 133 | F21: 전력 | G21: kWh | H21: =IF(SUM(I21:T21)=0,"",SUM(I21:T21)) | U21: 면적 배분
H22: =IF(SUM(I22:T22)=0,"",SUM(I22:T22))
H23: =IF(SUM(I23:T23)=0,"",SUM(I23:T23))
H24: =IF(SUM(I24:T24)=0,"",SUM(I24:T24))
H25: =IF(SUM(I25:T25)=0,"",SUM(I25:T25))
H26: =IF(SUM(I26:T26)=0,"",SUM(I26:T26))
H27: =IF(SUM(I27:T27)=0,"",SUM(I27:T27))
H28: =IF(SUM(I28:T28)=0,"",SUM(I28:T28))
H29: =IF(SUM(I29:T29)=0,"",SUM(I29:T29))
H30: =IF(SUM(I30:T30)=0,"",SUM(I30:T30))
H31: =IF(SUM(I31:T31)=0,"",SUM(I31:T31))
H32: =IF(SUM(I32:T32)=0,"",SUM(I32:T32))
H33: =IF(SUM(I33:T33)=0,"",SUM(I33:T33))
... H56: =IF(SUM(I56:T56)=0,"",SUM(I56:T56))

Sheet C8-3_인원
B2: C8. 업스트림 임차자산 3안. 인원수로 비율을 계산해야 할 때
B4: 카테고리 정의
B5: - 회사가 사용하는 임차자산의 에너지 사용량과 면적 정보를 직접 알 수 없는 경우 산정
B6: - 건물 전체 에너지 사용량은 알고 있으나 인원수 기준으로 배분해야 할 때 작성
B9: 작성 기준
B10: 1) 온실가스 산정 식: Σ((자사 인원수 / 건물전체 인원수) × 건물전체 에너지 사용량 × 에너지원별 배출계수)
B11: - 온실가스 배출 계수는 국가 승인 고유 배출계수(국내)와 IPCC 가이드라인 배출계수(해외), 환경부_환경성적표지(EPD) 배출계수를 활용
B12: 2) 건물전체 인원수와 자사 인원수는 반드시 작성
B13: 3) 면적 기준 자료가 있는 경우에는 인원수 기준보다 면적 기준 산정을 우선 적용
B16: ※ 사용 기준: 월별 자료가 있으면 1월~12월 칸에 입력하고, 연간 총량만 있으면 연간 입력 칸에 입력합니다. 동일 행에서 연간과 월별을 중복 입력하지 마세요.
B17: ※ 주황색으로 표시된 필수 입력칸은 반드시 작성해야 합니다.
B18: ※ 회색으로 표시된 입력란(배출계수, 배출량)은 자동으로 산출되므로 별도로 입력하지 않으셔도 됩니다.
B19: *국가 | C19: *임차자산명 | D19: *건물전체 인원수 | E19: *자사 인원수 | F19: *에너지종류 | G19: *단위 | H19: 연간 입력 | I19: 건물전체 월별사용량 | U19: 비고(선택) | V19: 배출계수(tCO2e/단위) | W19: 배출량(tCO2e)
H20: *건물전체 연간사용량 | I20: 1월 | J20: 2월 | K20: 3월 | L20: 4월 | M20: 5월 | N20: 6월 | O20: 7월 | P20: 8월 | Q20: 9월 | R20: 10월 | S20: 11월 | T20: 12월
B21: 대한민국 | C21: 임차자산 C | D21: 1432 | E21: 122 | F21: 전력 | G21: kWh | H21: =IF(SUM(I21:T21)=0,"",SUM(I21:T21)) | U21: 인원수 배분
H22: =IF(SUM(I22:T22)=0,"",SUM(I22:T22))
H23: =IF(SUM(I23:T23)=0,"",SUM(I23:T23))
H24: =IF(SUM(I24:T24)=0,"",SUM(I24:T24))
H25: =IF(SUM(I25:T25)=0,"",SUM(I25:T25))
H26: =IF(SUM(I26:T26)=0,"",SUM(I26:T26))
H27: =IF(SUM(I27:T27)=0,"",SUM(I27:T27))
H28: =IF(SUM(I28:T28)=0,"",SUM(I28:T28))
H29: =IF(SUM(I29:T29)=0,"",SUM(I29:T29))
H30: =IF(SUM(I30:T30)=0,"",SUM(I30:T30))
H31: =IF(SUM(I31:T31)=0,"",SUM(I31:T31))
H32: =IF(SUM(I32:T32)=0,"",SUM(I32:T32))
H33: =IF(SUM(I33:T33)=0,"",SUM(I33:T33))
... H56: =IF(SUM(I56:T56)=0,"",SUM(I56:T56))

Sheet C9-1_운송거리
B2: C9. 다운스트림 운송·배송 1안. 출발지·도착지 기반
B4: 카테고리 정의
B5: - 보고년도에 판매한 제품이 고객, 유통사, 대리점, 최종소비자 등으로 운송·배송되는 과정에서 발생하는 온실가스 배출량
B6: - 출발지와 도착지 또는 운송거리를 알고 있는 경우 작성
B9: 작성 기준
B10: 1) 온실가스 산정 식: Σ(화물중량 × 운송거리 × 운송수단별 배출계수)
B11: - 온실가스 배출계수는 환경부-환경성적표지(EPD) 평가계수를 활용
B12: 2) 운송수단은 도로, 해상, 항공, 철도 중 실제 주요 운송수단을 선택
B13: 3) C4 업스트림 운송·배송에 이미 포함된 운송은 중복 작성하지 않음
B16: ※ 사용 기준: 월별 자료가 있으면 1월~12월 칸에 입력하고, 연간 총량만 있으면 연간 입력 칸에 입력합니다. 동일 행에서 연간과 월별을 중복 입력하지 마세요.
B17: ※ 주황색으로 표시된 필수 입력칸은 반드시 작성해야 합니다.
B18: ※ 회색으로 표시된 입력란(배출계수, 배출량)은 자동으로 산출되므로 별도로 입력하지 않으셔도 됩니다.
B19: *국가 | C19: *사업장 | D19: *운송수단 | E19: *제품명 | F19: *중량단위 | G19: *출발지 | H19: *도착지 | I19: 운송거리(km)(선택) | J19: 연간 입력 | K19: 월별 운송량 | W19: 비고(선택) | X19: 배출계수(tCO2e/ton-km) | Y19: 배출량(tCO2e)
J20: 연간운송량 | K20: 1월 | L20: 2월 | M20: 3월 | N20: 4월 | O20: 5월 | P20: 6월 | Q20: 7월 | R20: 8월 | S20: 9월 | T20: 10월 | U20: 11월 | V20: 12월
B21: 대한민국 | C21: 본사 | D21: 도로 운송 (일반화물트럭) | E21: 제품 A | F21: ton | G21: 평택공장 | H21: 고객사 | I21: 200 | J21: =IF(SUM(K21:V21)=0,"",SUM(K21:V21)) | K21: 10 | L21: 10 | M21: 10 | N21: 10 | O21: 10 | P21: 10 | Q21: 10 | R21: 10 | S21: 10 | T21: 10 | U21: 10 | V21: 10 | W21: 출고 물류
J22: =IF(SUM(K22:V22)=0,"",SUM(K22:V22))
J23: =IF(SUM(K23:V23)=0,"",SUM(K23:V23))
J24: =IF(SUM(K24:V24)=0,"",SUM(K24:V24))
J25: =IF(SUM(K25:V25)=0,"",SUM(K25:V25))
J26: =IF(SUM(K26:V26)=0,"",SUM(K26:V26))
J27: =IF(SUM(K27:V27)=0,"",SUM(K27:V27))
J28: =IF(SUM(K28:V28)=0,"",SUM(K28:V28))
J29: =IF(SUM(K29:V29)=0,"",SUM(K29:V29))
J30: =IF(SUM(K30:V30)=0,"",SUM(K30:V30))
J31: =IF(SUM(K31:V31)=0,"",SUM(K31:V31))
J32: =IF(SUM(K32:V32)=0,"",SUM(K32:V32))
J33: =IF(SUM(K33:V33)=0,"",SUM(K33:V33))
... J56: =IF(SUM(K56:V56)=0,"",SUM(K56:V56))

Sheet C9-2_운송금액
B2: C9. 다운스트림 운송·배송 2안. 운송금액 기반
B4: 카테고리 정의
B5: - 보고년도에 판매한 제품의 하류 운송·배송 비용을 기준으로 산정하는 온실가스 배출량
B6: - 출발지, 도착지, 운송거리, 화물중량을 알 수 없고 운송비 또는 물류비만 확인 가능한 경우 작성
B9: 작성 기준
B10: 1) 온실가스 산정 식: Σ(운송지출금액 × 운송/물류 지출기반 배출계수)
B11: - 배출계수는 US EPA Supply Chain Greenhouse Gas Emission Factors v1.3 등 지출기반 배출계수 활용
B12: 2) 운송수단은 도로, 해상, 항공, 철도 중 실제 주요 운송수단을 선택
B13: 3) C4 업스트림 운송·배송에 이미 포함된 운송비는 중복 작성하지 않음
B16: ※ 사용 기준: 월별 자료가 있으면 1월~12월 칸에 입력하고, 연간 총량만 있으면 연간 입력 칸에 입력합니다. 동일 행에서 연간과 월별을 중복 입력하지 마세요.
B17: ※ 주황색으로 표시된 필수 입력칸은 반드시 작성해야 합니다.
B18: ※ 회색으로 표시된 입력란(배출계수, 배출량)은 자동으로 산출되므로 별도로 입력하지 않으셔도 됩니다.
B19: *국가 | C19: *사업장 | D19: *운송수단 | E19: *제품명 | F19: 거래처명(선택) | G19: 연간 입력 | H19: 월별 운송금액 | T19: 비고(선택) | U19: 배출계수(kgCO2e/원) | V19: 배출량(tCO2e)
G20: 연간운송금액(원) | H20: 1월 | I20: 2월 | J20: 3월 | K20: 4월 | L20: 5월 | M20: 6월 | N20: 7월 | O20: 8월 | P20: 9월 | Q20: 10월 | R20: 11월 | S20: 12월
B21: 대한민국 | C21: 본사 | D21: 화물트럭 운송 | E21: 제품 A | F21: 물류업체 | G21: =IF(SUM(H21:S21)=0,"",SUM(H21:S21)) | H21: 500000 | I21: 500000 | J21: 500000 | K21: 500000 | L21: 500000 | M21: 500000 | N21: 500000 | O21: 500000 | P21: 500000 | Q21: 500000 | R21: 500000 | S21: 500000 | T21: 배송비 기준
G22: =IF(SUM(H22:S22)=0,"",SUM(H22:S22))
G23: =IF(SUM(H23:S23)=0,"",SUM(H23:S23))
G24: =IF(SUM(H24:S24)=0,"",SUM(H24:S24))
G25: =IF(SUM(H25:S25)=0,"",SUM(H25:S25))
G26: =IF(SUM(H26:S26)=0,"",SUM(H26:S26))
G27: =IF(SUM(H27:S27)=0,"",SUM(H27:S27))
G28: =IF(SUM(H28:S28)=0,"",SUM(H28:S28))
G29: =IF(SUM(H29:S29)=0,"",SUM(H29:S29))
G30: =IF(SUM(H30:S30)=0,"",SUM(H30:S30))
G31: =IF(SUM(H31:S31)=0,"",SUM(H31:S31))
G32: =IF(SUM(H32:S32)=0,"",SUM(H32:S32))
G33: =IF(SUM(H33:S33)=0,"",SUM(H33:S33))
... G56: =IF(SUM(H56:S56)=0,"",SUM(H56:S56))

Sheet C11_판매제품사용
B2: C11. 판매제품 사용
B4: 카테고리 정의
B5: - 보고년도에 판매된 제품이 최종소비자에게 사용되는 과정에서 발생하는 온실가스 배출량
B6: - 에너지를 직접 소비하는 제품, 연료를 사용하는 제품, 사용 단계 배출이 중요한 제품이 대상
B9: 작성 기준
B10: 1) 온실가스 산정 식: Σ(판매수량 × 제품당 연간 에너지 사용량 × 평균 사용기간 × 에너지원별 배출계수)
B11: - 온실가스 배출계수는 환경부-환경성적표지(EPD) 평가계수를 활용
B12: 2) 제품별 판매량, 에너지명, 사용량, 사용기간은 반드시 작성
B13: 3) 제품 사용 단계 배출이 없는 제품은 작성하지 않음
B16: ※ 사용 기준: 제품/자산별 기초정보를 기준으로 작성합니다.
B17: ※ 주황색으로 표시된 필수 입력칸은 반드시 작성해야 합니다.
B18: ※ 회색으로 표시된 입력란(배출계수, 배출량)은 자동으로 산출되므로 별도로 입력하지 않으셔도 됩니다.
B19: *국가 | C19: 그룹(선택) | D19: *보고연도 | E19: *제품명 | F19: *제품수량 | G19: *에너지명 | H19: *제품당 연간 에너지 사용량 | I19: *단위 | J19: *수명(개월) 혹은 평균 사용기간(개월) | K19: 설명/적요(선택) | L19: 배출계수(tCO2e/단위) | M19: 배출량(tCO2e)
B21: 대한민국 | C21: 소형가전 | D21: 2025 | E21: 전기제품 A | F21: 1000 | G21: 전력 | H21: 150 | I21: kWh | J21: 60 | K21: 제품 사용 전력 | L21: AI 추천 | M21: AI 자동산정

Sheet C12_판매제품폐기
AA1: 대분류목록 | AC1: 대분류_매핑 | AD1: 중분류목록 | AF1: 중분류_매핑 | AG1: 소분류목록
B2: C12. 판매제품 폐기 | AA2: 선택안함 | AC2: 선택안함 | AD2: 선택안함 | AF2: 선택안함 | AG2: 선택안함
AA3: 지정 1 | 특정시설에서 발생하는 폐기물 | AC3: 지정 1 | 특정시설에서 발생하는 폐기물 | AD3: 01-01 | 폐합성고분자화합물 | AF3: 01-01 | 폐합성고분자화합물 | AG3: 01-01-01 | 폐폴리에틸렌
B4: 카테고리 정의 | AA4: 지정 3 | 유해물질 함유 폐기물 | AC4: 지정 1 | 특정시설에서 발생하는 폐기물 | AD4: 01-02 | 오니류 | AF4: 01-01 | 폐합성고분자화합물 | AG4: 01-01-02 | 폐폴리프로필렌
B5: - 보고년도에 판매된 제품이 수명 종료 후 폐기 및 처리되는 과정에서 발생하는 온실가스 배출량 | AA5: 사업장일반 51 | 사업장일반폐기물 | AC5: 지정 3 | 유해물질 함유 폐기물 | AD5: 03-01 | 광재 | AF5: 01-01 | 폐합성고분자화합물 | AG5: 01-01-03 | 폐폴리염화비닐수지
B6: - 판매 제품의 폐기, 소각, 재활용, 매립 등 최종 처리 단계 배출량 산정 | AA6: 생활 91 | 생활폐기물 | AC6: 지정 3 | 유해물질 함유 폐기물 | AD6: 03-05 | 소각재 | AF6: 01-01 | 폐합성고분자화합물 | AG6: 01-01-04 | 폐폴리에틸렌테레프탈레이트
AC7: 사업장일반 51 | 사업장일반폐기물 | AD7: 51-01 | 유기성오니류 | AF7: 01-01 | 폐합성고분자화합물 | AG7: 01-01-05 | 폐페놀수지
AC8: 사업장일반 51 | 사업장일반폐기물 | AD8: 51-02 | 무기성오니류 | AF8: 01-01 | 폐합성고분자화합물 | AG8: 01-01-06 | 폐폴리우레탄
B9: 작성 기준 | AC9: 사업장일반 51 | 사업장일반폐기물 | AD9: 51-03 | 폐지류 | AF9: 01-01 | 폐합성고분자화합물 | AG9: 01-01-07 | 폐합성고무
B10: 1) 온실가스 산정 식: Σ(판매수량 × 제품중량 × 폐기방식 비율 × 폐기방식별 배출계수) | AC10: 사업장일반 51 | 사업장일반폐기물 | AD10: 51-04 | 폐목재류 | AF10: 01-01 | 폐합성고분자화합물 | AG10: 01-01-08 | 폐폴리스티렌
B11: - 온실가스 배출계수는 환경부-환경성적표지(EPD) 평가계수를 활용하며, 사용자가 선택한 폐기물 분류를 내부 EPD 분류로 매핑합니다. | AC11: 사업장일반 51 | 사업장일반폐기물 | AD11: 51-05 | 폐합성수지류 | AF11: 01-01 | 폐합성고분자화합물 | AG11: 01-01-09 | 폐아크리로니트릴브타디엔스티렌(ABS 수지)
B12: 2) 폐기물 분류는 국립환경과학원 「폐기물 분류체계 및 분류방법 설명서」(2023) 및 폐기물관리법 시행규칙 [별표4](2023.8.11. 개정) 기준입니다. | AC12: 사업장일반 51 | 사업장일반폐기물 | AD12: 51-06 | 폐금속류 | AF12: 01-01 | 폐합성고분자화합물 | AG12: 01-01-99 | 그 밖의 폐합성고분자화합물
B13: - 폐기물 대분류를 먼저 선택하면, 해당 대분류에 맞는 중분류만 드롭다운에 표시됩니다. 폐기물 중분류를 선택하면, 해당 중분류에 맞는 소분류만 드롭다운에 표시됩니다. | AC13: 사업장일반 51 | 사업장일반폐기물 | AD13: 51-07 | 폐유리류 | AF13: 01-02 | 오니류 | AG13: 01-02-01 | 폐수처리오니
B14: - 모르면 비워두거나 선택안함을 선택합니다. | AC14: 사업장일반 51 | 사업장일반폐기물 | AD14: 51-08 | 폐콘크리트류 | AF14: 03-01 | 광재 | AG14: 03-01-01 | 제강분진
B15: 3) 제품중량과 제품중량 단위는 반드시 작성합니다. | AC15: 사업장일반 51 | 사업장일반폐기물 | AD15: 51-09 | 폐고무류 | AF15: 03-05 | 소각재 | AG15: 03-05-01 | 소각바닥재
B16: 4) 재활용, 소각, 매립, 기타 비중 합계는 100%가 되도록 작성합니다. 비율을 알 수 없는 경우에는 국가통계 기반 평균 비율을 추정하여 계산합니다. | AC16: 사업장일반 51 | 사업장일반폐기물 | AD16: 51-10 | 폐섬유류 | AF16: 51-01 | 유기성오니류 | AG16: 51-01-01 | 정수처리오니
B17: ※ 사용 기준: 판매 제품이 수명 종료 후 주로 어떤 폐기물로 처리되는지를 기준으로 작성합니다. | AC17: 사업장일반 51 | 사업장일반폐기물 | AD17: 51-14 | 폐전지류 | AF17: 51-01 | 유기성오니류 | AG17: 51-01-02 | 하수처리오니
B18: ※ 주황색으로 표시된 필수 입력칸은 반드시 작성해야 합니다. | AC18: 사업장일반 51 | 사업장일반폐기물 | AD18: 51-18 | 폐전기전자제품류 | AF18: 51-02 | 무기성오니류 | AG18: 51-02-01 | 폐수처리오니(무기성)
B19: ※ 회색으로 표시된 입력란(배출계수, 배출량)은 자동으로 산출되므로 별도로 입력하지 않으셔도 됩니다.
B20: *국가 | C20: 폐기물 대분류(선택) | D20: 폐기물 중분류(선택) | E20: 폐기물 소분류(선택) | F20: *제품명 | G20: *판매량 | H20: *제품중량 | I20: *제품중량 단위 | J20: 재활용 비중(%)(선택) | K20: 소각 비중(%)(선택) | L20: 매립 비중(%)(선택) | M20: 기타 비중(%)(선택) | N20: 설명/적요(선택) | O20: 배출계수(tCO2e/단위) | P20: 배출량(tCO2e) | AC20: 사업장일반 51 | 사업장일반폐기물 | AD20: 51-21 | 음식물류 폐기물 | AF20: 51-03 | 폐지류 | AG20: 51-03-01 | 신문지류
AC21: 사업장일반 51 | 사업장일반폐기물 | AD21: 51-99 | 51-99 | AF21: 51-03 | 폐지류 | AG21: 51-03-02 | 골판지류
B22: 대한민국 | C22: 지정 1 | 특정시설에서 발생하는 폐기물 | D22: 01-01 | 폐합성고분자화합물 | E22: 01-01-02 | 폐폴리프로필렌 | F22: 소형 전자제품 | G22: 1000 | H22: 0.3 | I22: kg | J22: 60 | K22: 20 | L22: 15 | M22: 5 | N22: 폐기 비율 기준 | AC22: 생활 91 | 생활폐기물 | AD22: 91-01 | 음식물류 폐기물 | AF22: 51-03 | 폐지류 | AG22: 51-03-03 | 잡지류
AC23: 생활 91 | 생활폐기물 | AD23: 91-02 | 폐지류 | AF23: 51-03 | 폐지류 | AG23: 51-03-04 | 백상지류
AC24: 생활 91 | 생활폐기물 | AD24: 91-03 | 폐금속캔류 | AF24: 51-03 | 폐지류 | AG24: 51-03-99 | 그 밖의 폐지류
AC25: 생활 91 | 생활폐기물 | AD25: 91-04 | 폐유리병류 | AF25: 51-04 | 폐목재류 | AG25: 51-04-01 | 폐건설목재
AC26: 생활 91 | 생활폐기물 | AD26: 91-05 | 폐합성수지류 | AF26: 51-04 | 폐목재류 | AG26: 51-04-02 | 폐팔레트
AC27: 생활 91 | 생활폐기물 | AD27: 91-06 | 폐의류 | AF27: 51-04 | 폐목재류 | AG27: 51-04-03 | 폐가구류
AC28: 생활 91 | 생활폐기물 | AD28: 91-07 | 폐가전제품 | AF28: 51-04 | 폐목재류 | AG28: 51-04-99 | 그 밖의 폐목재류
AC29: 생활 91 | 생활폐기물 | AD29: 91-08 | 폐가구류 | AF29: 51-05 | 폐합성수지류 | AG29: 51-05-01 | 폐PE
AC30: 생활 91 | 생활폐기물 | AD30: 91-09 | 폐목재류 | AF30: 51-05 | 폐합성수지류 | AG30: 51-05-02 | 폐PP
AC31: 생활 91 | 생활폐기물 | AD31: 91-99 | 91-99 | AF31: 51-05 | 폐합성수지류 | AG31: 51-05-03 | 폐PVC
AF32: 51-05 | 폐합성수지류 | AG32: 51-05-04 | 폐PET
AF33: 51-05 | 폐합성수지류 | AG33: 51-05-05 | 폐PS
AF34: 51-05 | 폐합성수지류 | AG34: 51-05-06 | 폐ABS수지
AF35: 51-05 | 폐합성수지류 | AG35: 51-05-07 | 폐EPS(스티로폼)
AF36: 51-05 | 폐합성수지류 | AG36: 51-05-99 | 그 밖의 폐합성수지류
AF37: 51-06 | 폐금속류 | AG37: 51-06-01 | 폐철류
AF38: 51-06 | 폐금속류 | AG38: 51-06-02 | 폐동류
AF39: 51-06 | 폐금속류 | AG39: 51-06-03 | 폐알루미늄류
AF40: 51-06 | 폐금속류 | AG40: 51-06-04 | 폐납류
...

Sheet C13-1_에너지사용량 아는경우
B2: C13. 다운스트림 임대자산 1안. 에너지 사용량을 알고 있을 때
B4: 카테고리 정의
B5: - 보고년도에 회사가 임대자산으로 사용하는 자산에서 발생하는 온실가스 배출량
B6: - 해당 자산의 실제 에너지 사용량을 알고 있을 때 작성
B9: 작성 기준
B10: 1) 온실가스 산정 식: Σ(에너지 사용량 × 에너지원별 배출계수)
B11: - 온실가스 배출 계수는 국가 승인 고유 배출계수(국내)와 IPCC 가이드라인 배출계수(해외), 환경부_환경성적표지(EPD) 배출계수를 활용
B12: 2) 원자료는 반드시 작성하고 데이터는 연간 또는 월별 작성 가능
B13: 3) 한 자산에서 1개 이상 에너지원을 사용하는 경우 에너지원별로 행을 나누어 작성
B16: ※ 사용 기준: 월별 자료가 있으면 1월~12월 칸에 입력하고, 연간 총량만 있으면 연간 입력 칸에 입력합니다. 동일 행에서 연간과 월별을 중복 입력하지 마세요.
B17: ※ 주황색으로 표시된 필수 입력칸은 반드시 작성해야 합니다.
B18: ※ 회색으로 표시된 입력란(배출계수, 배출량)은 자동으로 산출되므로 별도로 입력하지 않으셔도 됩니다.
B19: *국가 | C19: *임대자산명 | D19: *에너지종류 | F19: 연간 입력 | G19: 월별 사용량 | T19: 배출계수(tCO2e/단위) | U19: 배출량(tCO2e)
E20: *단위 | F20: 연간사용량 | G20: 1월 | H20: 2월 | I20: 3월 | J20: 4월 | K20: 5월 | L20: 6월 | M20: 7월 | N20: 8월 | O20: 9월 | P20: 10월 | Q20: 11월 | R20: 12월 | S20: 비고(선택)
B21: 대한민국 | C21: 임대자산 A | D21: 전력 | E21: kWh | F21: =IF(SUM(G21:R21)=0,"",SUM(G21:R21)) | G21: 10000 | H21: 10000 | I21: 10000 | J21: 10000 | K21: 10000 | L21: 10000 | M21: 10000 | N21: 10000 | O21: 10000 | P21: 10000 | Q21: 10000 | R21: 10000 | S21: 전력 사용량
F22: =IF(SUM(G22:R22)=0,"",SUM(G22:R22))
F23: =IF(SUM(G23:R23)=0,"",SUM(G23:R23))
F24: =IF(SUM(G24:R24)=0,"",SUM(G24:R24))
F25: =IF(SUM(G25:R25)=0,"",SUM(G25:R25))
F26: =IF(SUM(G26:R26)=0,"",SUM(G26:R26))
F27: =IF(SUM(G27:R27)=0,"",SUM(G27:R27))
F28: =IF(SUM(G28:R28)=0,"",SUM(G28:R28))
F29: =IF(SUM(G29:R29)=0,"",SUM(G29:R29))
F30: =IF(SUM(G30:R30)=0,"",SUM(G30:R30))
F31: =IF(SUM(G31:R31)=0,"",SUM(G31:R31))
F32: =IF(SUM(G32:R32)=0,"",SUM(G32:R32))
F33: =IF(SUM(G33:R33)=0,"",SUM(G33:R33))
... F56: =IF(SUM(G56:R56)=0,"",SUM(G56:R56))

Sheet C13-2_면적
B2: C13. 다운스트림 임대자산 2안. 건물전체 에너지사용량만 알고 있을 때
B4: 카테고리 정의
B5: - 회사가 사용하는 임대자산의 에너지 사용량을 직접 알 수 없는 경우 산정
B6: - 건물 전체 에너지 사용량은 알고 있으나 면적 기준으로 배분해야 할 때 작성
B9: 작성 기준
B10: 1) 온실가스 산정 식: Σ((사용 면적 / 건물전체 면적) × 건물전체 에너지 사용량 × 에너지원별 배출계수)
B11: - 온실가스 배출 계수는 국가 승인 고유 배출계수(국내)와 IPCC 가이드라인 배출계수(해외), 환경부_환경성적표지(EPD) 배출계수를 활용
B12: 2) 건물전체 면적과 사용 면적은 반드시 작성
B13: 3) 원자료는 반드시 작성하고 데이터는 연간 또는 월별 작성 가능
B16: ※ 사용 기준: 월별 자료가 있으면 1월~12월 칸에 입력하고, 연간 총량만 있으면 연간 입력 칸에 입력합니다. 동일 행에서 연간과 월별을 중복 입력하지 마세요.
B17: ※ 주황색으로 표시된 필수 입력칸은 반드시 작성해야 합니다.
B18: ※ 회색으로 표시된 입력란(배출계수, 배출량)은 자동으로 산출되므로 별도로 입력하지 않으셔도 됩니다.
B19: *국가 | C19: *임대자산명 | D19: *건물전체 면적 | E19: *사용 면적 | F19: *에너지종류 | G19: *단위 | H19: 연간 입력 | I19: 건물전체 월별사용량 | U19: 비고(선택) | V19: 배출계수(tCO2e/단위) | W19: 배출량(tCO2e)
H20: *건물전체 연간사용량 | I20: 1월 | J20: 2월 | K20: 3월 | L20: 4월 | M20: 5월 | N20: 6월 | O20: 7월 | P20: 8월 | Q20: 9월 | R20: 10월 | S20: 11월 | T20: 12월
B21: 대한민국 | C21: 임대자산 B | D21: 13908 | E21: 133 | F21: 전력 | G21: kWh | H21: =IF(SUM(I21:T21)=0,"",SUM(I21:T21)) | U21: 면적 배분
H22: =IF(SUM(I22:T22)=0,"",SUM(I22:T22))
H23: =IF(SUM(I23:T23)=0,"",SUM(I23:T23))
H24: =IF(SUM(I24:T24)=0,"",SUM(I24:T24))
H25: =IF(SUM(I25:T25)=0,"",SUM(I25:T25))
H26: =IF(SUM(I26:T26)=0,"",SUM(I26:T26))
H27: =IF(SUM(I27:T27)=0,"",SUM(I27:T27))
H28: =IF(SUM(I28:T28)=0,"",SUM(I28:T28))
H29: =IF(SUM(I29:T29)=0,"",SUM(I29:T29))
H30: =IF(SUM(I30:T30)=0,"",SUM(I30:T30))
H31: =IF(SUM(I31:T31)=0,"",SUM(I31:T31))
H32: =IF(SUM(I32:T32)=0,"",SUM(I32:T32))
H33: =IF(SUM(I33:T33)=0,"",SUM(I33:T33))
... H56: =IF(SUM(I56:T56)=0,"",SUM(I56:T56))

Sheet C13-3_인원
B2: C13. 다운스트림 임대자산 3안. 인원수로 비율을 계산해야 할 때
B4: 카테고리 정의
B5: - 회사가 사용하는 임대자산의 에너지 사용량과 면적 정보를 직접 알 수 없는 경우 산정
B6: - 건물 전체 에너지 사용량은 알고 있으나 인원수 기준으로 배분해야 할 때 작성
B9: 작성 기준
B10: 1) 온실가스 산정 식: Σ((자사 인원수 / 건물전체 인원수) × 건물전체 에너지 사용량 × 에너지원별 배출계수)
B11: - 온실가스 배출 계수는 국가 승인 고유 배출계수(국내)와 IPCC 가이드라인 배출계수(해외), 환경부_환경성적표지(EPD) 배출계수를 활용
B12: 2) 건물전체 인원수와 자사 인원수는 반드시 작성
B13: 3) 면적 기준 자료가 있는 경우에는 인원수 기준보다 면적 기준 산정을 우선 적용
B16: ※ 사용 기준: 월별 자료가 있으면 1월~12월 칸에 입력하고, 연간 총량만 있으면 연간 입력 칸에 입력합니다. 동일 행에서 연간과 월별을 중복 입력하지 마세요.
B17: ※ 주황색으로 표시된 필수 입력칸은 반드시 작성해야 합니다.
B18: ※ 회색으로 표시된 입력란(배출계수, 배출량)은 자동으로 산출되므로 별도로 입력하지 않으셔도 됩니다.
B19: *국가 | C19: *임대자산명 | D19: *건물전체 인원수 | E19: *자사 인원수 | F19: *에너지종류 | G19: *단위 | H19: 연간 입력 | I19: 건물전체 월별사용량 | U19: 비고(선택) | V19: 배출계수(tCO2e/단위) | W19: 배출량(tCO2e)
H20: *건물전체 연간사용량 | I20: 1월 | J20: 2월 | K20: 3월 | L20: 4월 | M20: 5월 | N20: 6월 | O20: 7월 | P20: 8월 | Q20: 9월 | R20: 10월 | S20: 11월 | T20: 12월
B21: 대한민국 | C21: 임대자산 C | D21: 1432 | E21: 122 | F21: 전력 | G21: kWh | H21: =IF(SUM(I21:T21)=0,"",SUM(I21:T21)) | U21: 인원수 배분
H22: =IF(SUM(I22:T22)=0,"",SUM(I22:T22))
H23: =IF(SUM(I23:T23)=0,"",SUM(I23:T23))
H24: =IF(SUM(I24:T24)=0,"",SUM(I24:T24))
H25: =IF(SUM(I25:T25)=0,"",SUM(I25:T25))
H26: =IF(SUM(I26:T26)=0,"",SUM(I26:T26))
H27: =IF(SUM(I27:T27)=0,"",SUM(I27:T27))
H28: =IF(SUM(I28:T28)=0,"",SUM(I28:T28))
H29: =IF(SUM(I29:T29)=0,"",SUM(I29:T29))
H30: =IF(SUM(I30:T30)=0,"",SUM(I30:T30))
H31: =IF(SUM(I31:T31)=0,"",SUM(I31:T31))
H32: =IF(SUM(I32:T32)=0,"",SUM(I32:T32))
H33: =IF(SUM(I33:T33)=0,"",SUM(I33:T33))
... H56: =IF(SUM(I56:T56)=0,"",SUM(I56:T56))

Sheet C14_프랜차이즈
B2: C14. 프랜차이즈
B4: 카테고리 정의
B5: - 보고년도 내 당사의 브랜드 사용권을 부여받아 운영 중인 모든 가맹점(프랜차이즈) 내에서 발생한 온실가스 배출량
B6: - 대상: 가맹점 운영을 위해 소비된 모든 연료 및 전력 사용량
B9: 작성 기준
B10: 1) 온실가스 산정 식: Σ(가맹점 활동 유형별 사용량 × 에너지원별 배출계수)
B11: - 온실가스 배출계수는 국내인 경우 승인 국가 온실가스 배출계수, 국외인 경우 IPCC 가이드라인 배출계수를 활용
B12: 2) 국가, 가맹점 수, 전력사용량, 전력사용량 단위는 반드시 작성
B13: 3) 연료 사용이 있는 경우 연료 종류, 연료 사용량, 연료 단위를 함께 작성
B14: 4) 동일 국가·프랜차이즈에서 전력과 복수 연료를 사용하는 경우 에너지원별로 행을 나누어 작성 가능
B16: ※ 사용 기준: 브랜드별/국가별 가맹점 운영에 사용된 전력 및 연료 사용량을 기준으로 작성합니다.
B17: ※ 주황색으로 표시된 필수 입력칸은 반드시 작성해야 합니다.
B18: ※ 회색으로 표시된 입력란(배출계수, 배출량)은 자동으로 산출되므로 별도로 입력하지 않으셔도 됩니다.
B19: *국가 | C19: *프랜차이즈명 | D19: *가맹점 수 | E19: *연료 종류 | F19: *연료 사용량 | G19: *연료 단위 | H19: 배출계수(tCO2e/단위) | I19: 배출량(tCO2e)
B20: 대한민국 | C20: 뚜레쥬르 | D20: 13 | E20: 도시가스(LNG) | F20: 25 | G20: Nm³
B21: 대한민국 | C21: 올리브영 | D21: 256 | E21: 천연가스(LNG) | F21: 780 | G21: kg

Sheet C15_투자
B2: C15. 투자
B4: 작성 기준
B5: 1. 본 템플릿은 보고년도에 당사가 수행한 투자활동(지분 투자 등)으로 인해 발생한 온실가스를 산정하기 위한 항목입니다.
B6: - 대상: 당사가 투자를 진행한 피투자기업, 프로젝트, 또는 금융 자산 운영 과정에서 발생하는 배출량
B7: 2. 온실가스 산정식은 아래와 같습니다.
B8: <참고> Σ (투자 대상의 Scope 1&2 배출량 × 당사의 지분 비율)
B10: ※ 지분 비율은 보고년도 말 기준 당사가 보유한 의결권 또는 자산 가치 비율을 의미합니다.
B11: ※ Scope 1&2 배출량은 tCO2e 기준으로 입력합니다.
B12: ※ 주황색으로 표시된 필수 입력칸은 반드시 작성해야 합니다.
B13: ※ 회색으로 표시된 입력란(배출계수, 배출량)은 자동으로 산출되므로 별도로 입력하지 않으셔도 됩니다.
B14: 피투자기업명 (필수) | C14: 지분율(%) (선택) | D14: *피투자기업 Scope1배출량 | E14: *피투자기업 Scope2배출량 | F14: 산정 배출량(tCO2e)
F15: =IF(OR(B15="",C15="",D15="",E15=""),"",(D15+E15)*C15/100)
F16: =IF(OR(B16="",C16="",D16="",E16=""),"",(D16+E16)*C16/100)
F17: =IF(OR(B17="",C17="",D17="",E17=""),"",(D17+E17)*C17/100)
F18: =IF(OR(B18="",C18="",D18="",E18=""),"",(D18+E18)*C18/100)
F19: =IF(OR(B19="",C19="",D19="",E19=""),"",(D19+E19)*C19/100)
F20: =IF(OR(B20="",C20="",D20="",E20=""),"",(D20+E20)*C20/100)
F21: =IF(OR(B21="",C21="",D21="",E21=""),"",(D21+E21)*C21/100)
F22: =IF(OR(B22="",C22="",D22="",E22=""),"",(D22+E22)*C22/100)
F23: =IF(OR(B23="",C23="",D23="",E23=""),"",(D23+E23)*C23/100)
F24: =IF(OR(B24="",C24="",D24="",E24=""),"",(D24+E24)*C24/100)
F25: =IF(OR(B25="",C25="",D25="",E25=""),"",(D25+E25)*C25/100)

Sheet 배출계수_드롭다운
A1: DD_PURCHASE_GROUP | B1: DD_ENERGY | C1: DD_ENERGY_UNIT | D1: DD_TRANSPORT_DISTANCE | E1: DD_TRANSPORT_SPEND | F1: DD_TRAVEL_DISTANCE | G1: DD_TRAVEL_SPEND | H1: DD_WASTE_C5_TYPE | I1: DD_WASTE_METHOD | J1: DD_WASTE_UNIT | K1: DD_TRANSPORT_WEIGHT_UNIT | M1: C6/C7 거리기반 상세 매핑
A2: C1/C2 구매·자본재 품목군 | B2: C3/C8/C11/C13/C14 에너지명 | C2: 에너지 기준단위 | D2: C4/C9 거리기반 운송수단 | E2: C4/C9 금액기반 운송항목 | F2: C6/C7 거리기반 교통수단 | G2: C6 금액기반 출장항목 | H2: C5 폐기물 종류 | I2: 폐기물 처리방법 | J2: 폐기물 중량단위 | K2: 운송 중량단위 | M2: 표시값(드롭다운) | N2: 표준코드 | O2: DEFRA Type | P2: 매핑 키워드
A3: 원재료/부자재 | B3: 도시가스(LNG) | C3: kWh | D3: 도로 운송 (일반화물트럭) | E3: 항공 운송(여객·화물·전세) | F3: 항공(국제선 평균) | G3: 항공권(여객·전세) | H3: 음식물류 폐기물 | I3: 매립 | J3: kg | K3: kg | M3: 항공(국제선 평균) | N3: flight | O3: International, non-UK - Average passenger | P3: 항공,비행기,비행,airplane,flight,국제선,해외출장
A4: 포장재 | B4: 천연가스(LNG) | C4: GJ | D4: 도로 운송 (택배·소화물) | E4: 철도 운송 | F4: 국내선 항공 | G4: 택시·리무진 비용 | H4: 폐지류 | I4: 소각 | J4: ton | K4: ton | M4: 국내선 항공 | N4: flight_dom | O4: Domestic, to/from UK - Average | P4: 국내선,국내항공,국내비행,domestic
A5: 사무용품 | B5: CNG(차량) | C5: L | D5: 철도 운송 | E5: 해상 운송(원양) | F5: 페리 | G5: 시외버스·고속버스 요금 | H5: 폐플라스틱류 | I5: 재활용 | M5: 페리 | N5: ferry | O5: Average (all passenger) | P5: 페리,ferry,선박,배
A6: 탕비·식음료 | B6: LNG(차량) | C6: kg | D6: 해상 운송 (컨테이너선) | E6: 내륙 수로 화물 | F6: 버스 | G6: 기차·KTX 요금 | H6: 폐목재류 | I6: 기타 | M6: 버스 | N6: bus | O6: Average local bus | P6: 버스,bus,고속버스,시외버스,시내버스,광역버스,전세버스,셔틀
A7: IT장비 | B7: LPG(차량) | C7: Nm³ | D7: 해상 운송 (벌크선) | E7: 화물 트럭(지역·이사) | F7: 장거리버스/코치 | G7: 렌터카·렌트 트럭 | H7: 폐섬유류 | M7: 장거리버스/코치 | N7: coach | O7: Coach | P7: 코치,장거리버스,express bus
A8: 사무가구·비품 | B8: 도시가스(LPG) | D8: 항공 운송 | E8: 장거리 화물 트럭 (차량단위) | F8: 철도/KTX/SRT | G8: 숙박비(호텔·게스트하우스 등) | H8: 폐유리류 | M8: 철도/KTX/SRT | N8: train | O8: National rail | P8: 기차,KTX,SRT,ITX,새마을,무궁화,열차,철도
A9: 시설·유지보수 | B9: 액화석유가스(LPG) | D9: 내륙수로 운송 | E9: 장거리 화물 트럭 (혼재) | F9: 지하철/도시철도 | H9: 폐금속류 | M9: 지하철/도시철도 | N9: subway | O9: London Underground / Metro | P9: 지하철,subway,metro,전철,도시철도
A10: 외주·서비스 | B10: 경유 | E10: 특수화물 트럭 (장거리) | F10: 택시 | H10: 오니류 | M10: 택시 | N10: taxi | O10: Regular taxi | P10: 택시,taxi,cab,카카오t,카카오택시,우버,uber
A11: 에너지·유틸리티 | B11: 실내 등유 | E11: 복합 대중교통 | F11: 승용차(평균) | H11: 폐전기전자제품 | M11: 승용차(평균) | N11: car | O11: Average car | P11: 승용차,자가용,car,차량,렌터카,자동차
A12: 차량·운송장비 | B12: 항공유 | E12: 버스(대중교통·통근·전세) | F12: 하이브리드차 | H12: 폐배터리 | M12: 하이브리드차 | N12: car_hybrid | O12: PHEV - Method 2 | P12: 하이브리드,hybrid,HEV,PHEV,플러그인하이브리드
A13: 생산설비 | B13: 휘발유 | E13: 기타 도시교통 | F13: 전기차 | H13: 폐유류 | M13: 전기차 | N13: car_ev | O13: BEV | P13: 전기차,전기자동차,EV,BEV,테슬라,아이오닉,EV6
A14: 안전·위생 | B14: 전력 | E14: 도시간·농촌 버스 | F14: 오토바이 | H14: 폐콘크리트류 | M14: 오토바이 | N14: motorcycle | O14: Average | P14: 오토바이,motorcycle,바이크
A15: 건설자재 | B15: 열(스팀) | E15: 택시·리무진 | F15: 도보/자전거 | H15: 폐고무/피혁류 | M15: 도보/자전거 | N15: walk | O15: 도보·자전거 | P15: 도보,자전거,walk,bicycle,bike
A16: 통신·미디어 | B16: 선택안함 | E16: 원유 파이프라인 | H16: 지정폐기물
A17: 여행·숙박 | E17: 화물운송 주선 (포워딩) | H17: 기타
A18: 기타 | E18: 택배·퀵배송 | H18: [전체 평균]
A19: 선택안함 | E19: 지역 배달
A38: ※ 본 시트의 드롭다운 목록은 업로드된 「배출계수_통합_DB」의 각 시트 값을 기준으로 생성했습니다. 템플릿의 입력값과 DB 기준명이 다른 경우에는 「드롭다운_매핑검토」의 매핑표를 참고하세요.

Sheet 드롭다운_매핑검토
A1: 구분 | B1: 템플릿 시트/범위 | C1: 기존 드롭다운/예시값 | D1: DB 기준 변경값 | E1: 조치
A2: 구매/자본재 | B2: C1 D20:D219, C2 D20:D219 | C2: 기존 품목군/자산분류 일부 | D2: 구매_USEPA!품목군 기준 | E2: DB 품목군으로 통일
A3: 에너지 | B3: C3/C8/C11/C13/C14 에너지명 | C3: 전기, 스팀, LPG 등 | D3: 에너지!활동유형(에너지원) 기준 | E3: 전기→전력, 스팀→열(스팀), LPG→액화석유가스(LPG) 등 매핑
A4: 에너지 단위 | B4: 에너지 단위 컬럼 | C4: m3, Nm3 등 | D4: 에너지!투입량 기준단위 기준 | E4: Nm³ 등 DB 표기 통일
A5: 운송 거리기반 | B5: C4-1/C9-1 운송수단 | C5: 도로/해상/항공/철도 | D5: 운송!운송수단(EPD 원본명) 기준 | E5: 세부 EF 단위로 상세화 및 내륙수로 추가
A6: 운송 금액기반 | B6: C4-2/C9-2 운송수단 | C6: 도로/해상/항공/철도 | D6: 운송_Spend!한국어 품목명 기준 | E6: 화물트럭 운송, 정기 항공화물 등으로 상세화 → 이후 배출계수(EF)가 완전히 동일한 항목끼리 재통합 (27→17개, 배출계수_통합_DB.xlsx의 운송_Spend 시트도 동일 기준으로 병합)
A7: 출장/통근 거리기반 | B7: C6-1/C7 교통수단 | C7: 자동차, 철도(KTX/SRT) 등 | D7: 출장_통근!표준코드/키워드 기준 | E7: DB 표준코드와 연결되는 한국어 표시값으로 정리 → 실사용 데이터(공연공 실적 1,200여 행) 기준 33개 중 실제로 쓰인 건 9개뿐이라, 좌석등급·차량크기 등 세부 구분(비즈니스/이코노미, 소형/중형/대형 등)을 13개로 축소(파이프라인 TRAVEL_EF_MAP의 세부 EF 코드 자체는 그대로 보존, 드롭다운만 정리)
A8: 출장비 | B8: C6-2 출장항목 | C8: 항공/철도/택시/렌터카/숙박/기타 | D8: 출장_Spend!한국어 품목명 기준 | E8: 여객 항공권, 기차·KTX 요금 등으로 상세화 → EF가 동일한 항목 병합 + 식비/통신비(DB에 배출계수 없음) 제거로 14→6개 축소, 배출계수_통합_DB.xlsx의 출장_Spend 시트도 동일 기준으로 병합
A9: 사업장폐기물 | B9: C5 폐기물종류/처리방법 | C9: 템플릿 임의목록 | D9: 폐기물_C5 기준 | E9: DB에 없는 항목은 지정폐기물/기타 등으로 매핑
A10: 판매제품폐기 | B10: C12 대/중/소분류 | C10: 기존 전체 법정 분류 목록 | D10: 폐기물_C12에 계수 있는 항목만 | E10: 소분류까지 DB 보유 항목 중심으로 축소·재구성
A11: 회사별 자동매칭 | B11: C5 폐기물종류 / C6-1·C7 교통수단 | C11: (신규 기능) | D11: '회사별_폐기물매핑'/'회사별_교통수단매핑' 시트 | E11: 표지(기업정보)에서 회사 선택 → 상세명(E열/Y열) 입력 시 표준값이 자동 매칭되는 수식 추가. 회사 목록은 '기업정보' 시트 E열에서 관리하고, 두 매핑 시트는 그 값을 그대로 참조
A12: 항공 거리계산(C6-1/C7) | B12: get_distance_km(mode="air") | C12: 주소 기준 직선거리 × 1.05 | D12: Climatiq/ICAO/DEFRA 벤치마킹 결과 | E12: 출도착지가 공항이 아니라 주소·지명이면 AI가 그 지역의 가까운 주요 공항으로 치환한 뒤 공항-공항 간 거리로 계산하도록 수정, 우회보정 계수도 1.05 → 1.09로 상향
A13: 주요 기존값 → DB 기준값 매핑
A14: 매핑그룹 | B14: 기존값 | C14: DB 기준값
A15: purchase_group | B15: 원재료 | C15: 원재료/부자재
A16: purchase_group | B16: 부자재 | C16: 원재료/부자재
A17: purchase_group | B17: 종이/인쇄물 | C17: 사무용품
A18: purchase_group | B18: IT/전자장비 | C18: IT장비
A19: purchase_group | B19: 소모품 | C19: 사무용품
A20: purchase_group | B20: 화학물질 | C20: 원재료/부자재
A21: purchase_group | B21: 금속/철강 | C21: 원재료/부자재
A22: purchase_group | B22: 플라스틱/고무 | C22: 원재료/부자재
A23: purchase_group | B23: 섬유/의류 | C23: 원재료/부자재
A24: purchase_group | B24: 식음료 | C24: 탕비·식음료
A25: purchase_group | B25: 운송/물류서비스 | C25: 외주·서비스
... A134: unit | B134: MJ | C134: MJ

Sheet 회사별_폐기물매핑
A1: 회사명 | B1: 상세 폐기물명 | C1: 폐기물 종류 | E1: 회사 목록(드롭다운용) | G1: '예시기업'는 형식을 보여주는 예시입니다. 회사 목록은 이 시트가 아니라 '기업정보' 시트의 E열에서 관리합니다(이 시트 E열은 그 값을 그대로 표시). 새 회사를 추가하려면: ① 이 시트 A~C열에 그 회사의 '상세 폐기물명 → 폐기물 종류' 행을 추가하고 ② '기업정보' 시트 E열에 회사명을 한 줄 추가하세요.
A2: 공연공 | B2: 일반쓰레기 | C2: 기타 | E2: =IF(기업정보!E2="","",기업정보!E2)
A3: 공연공 | B3: 폐아스발트 | C3: 폐콘크리트류 | E3: =IF(기업정보!E3="","",기업정보!E3)
A4: 공연공 | B4: 폐합성수지 | C4: 폐플라스틱류 | E4: =IF(기업정보!E4="","",기업정보!E4)
A5: 공연공 | B5: 폐산 | C5: 기타 | E5: =IF(기업정보!E5="","",기업정보!E5)
A6: 공연공 | B6: 임목폐기물 | C6: 폐목재류 | E6: =IF(기업정보!E6="","",기업정보!E6)
A7: 공연공 | B7: 잔디예지물 | C7: 기타 | E7: =IF(기업정보!E7="","",기업정보!E7)
A8: 공연공 | B8: 폐토사 | C8: 기타 | E8: =IF(기업정보!E8="","",기업정보!E8)
A9: 공연공 | B9: 액상 폐유 | C9: 폐유류 | E9: =IF(기업정보!E9="","",기업정보!E9)
A10: 공연공 | B10: 고상 폐유 | C10: 폐유류 | E10: =IF(기업정보!E10="","",기업정보!E10)
A11: 공연공 | B11: 폐농약병 | C11: 지정폐기물 | E11: =IF(기업정보!E11="","",기업정보!E11)
A12: 공연공 | B12: 폐타이어 | C12: 폐고무/피혁류 | E12: =IF(기업정보!E12="","",기업정보!E12)
A13: 공연공 | B13: 기타 | C13: 기타 | E13: =IF(기업정보!E13="","",기업정보!E13)
... A15: 공연공 | B15: 불연성생활쓰레기 | C15: 기타 | E15: =IF(기업정보!E15="","",기업정보!E15)
E16: =IF(기업정보!E16="","",기업정보!E16)
E17: =IF(기업정보!E17="","",기업정보!E17)
E18: =IF(기업정보!E18="","",기업정보!E18)
E19: =IF(기업정보!E19="","",기업정보!E19)
E20: =IF(기업정보!E20="","",기업정보!E20)
E21: =IF(기업정보!E21="","",기업정보!E21)
E22: =IF(기업정보!E22="","",기업정보!E22)
E23: =IF(기업정보!E23="","",기업정보!E23)
E24: =IF(기업정보!E24="","",기업정보!E24)
E25: =IF(기업정보!E25="","",기업정보!E25)
E26: =IF(기업정보!E26="","",기업정보!E26)
E27: =IF(기업정보!E27="","",기업정보!E27)
... E50: =IF(기업정보!E50="","",기업정보!E50)

Sheet 회사별_교통수단매핑
A1: 회사명 | B1: 상세 교통수단명 | C1: 표준 교통수단 | E1: 회사 목록(드롭다운용) | G1: '예시기업'는 형식을 보여주는 예시입니다. 회사 목록은 이 시트가 아니라 '기업정보' 시트의 E열에서 관리합니다(이 시트 E열은 그 값을 그대로 표시). 새 회사를 추가하려면: ① 이 시트 A~C열에 그 회사의 '상세 교통수단명 → 표준 교통수단' 행을 추가하고 ② '기업정보' 시트 E열에 회사명을 한 줄 추가하세요. 표준 교통수단은 반드시 '배출계수_드롭다운' 시트 F열(DD_TRAVEL_DISTANCE) 목록 값과 똑같이 입력해야 합니다.
A2: 공연공 | B2: KTX | C2: 철도/KTX/SRT | E2: =IF(기업정보!E2="","",기업정보!E2)
A3: 공연공 | B3: 무궁화호 | C3: 철도/KTX/SRT | E3: =IF(기업정보!E3="","",기업정보!E3)
A4: 예시기업 | B4: 일반 택시 | C4: 택시 | E4: =IF(기업정보!E4="","",기업정보!E4)
A5: 예시기업 | B5: 카카오T | C5: 택시 | E5: =IF(기업정보!E5="","",기업정보!E5)
A6: 예시기업 | B6: 국내선 비행기 | C6: 국내선 항공 | E6: =IF(기업정보!E6="","",기업정보!E6)
A7: 예시기업 | B7: 도보 출퇴근 | C7: 도보/자전거 | E7: =IF(기업정보!E7="","",기업정보!E7)
A8: 예시기업 | B8: 회사 통근버스 | C8: 버스 | E8: =IF(기업정보!E8="","",기업정보!E8)
E9: =IF(기업정보!E9="","",기업정보!E9)
E10: =IF(기업정보!E10="","",기업정보!E10)
E11: =IF(기업정보!E11="","",기업정보!E11)
E12: =IF(기업정보!E12="","",기업정보!E12)
E13: =IF(기업정보!E13="","",기업정보!E13)
E14: =IF(기업정보!E14="","",기업정보!E14)
E15: =IF(기업정보!E15="","",기업정보!E15)
E16: =IF(기업정보!E16="","",기업정보!E16)
E17: =IF(기업정보!E17="","",기업정보!E17)
E18: =IF(기업정보!E18="","",기업정보!E18)
E19: =IF(기업정보!E19="","",기업정보!E19)
E20: =IF(기업정보!E20="","",기업정보!E20)
... E50: =IF(기업정보!E50="","",기업정보!E50)
