Workbook
Name DD_APPLIED_COMPANY: 기업정보!$E$2:$E$50
Name DD_ENERGY: 배출계수_드롭다운!$B$3:$B$17
Name DD_ENERGY_UNIT: 배출계수_드롭다운!$C$3:$C$7
Name DD_PURCHASE_GROUP: 배출계수_드롭다운!$A$3:$A$19
Name DD_TRANSPORT_DISTANCE: 배출계수_드롭다운!$D$3:$D$9
Name DD_TRANSPORT_SPEND: 배출계수_드롭다운!$E$3:$E$19
Name DD_TRANSPORT_WEIGHT_UNIT: 배출계수_드롭다운!$K$3:$K$4
Name DD_TRAVEL_DISTANCE: 배출계수_드롭다운!$F$3:$F$15
Name DD_TRAVEL_SPEND: 배출계수_드롭다운!$G$3:$G$8
Name DD_WASTE_C5_TYPE: 배출계수_드롭다운!$H$3:$H$18
Name DD_WASTE_METHOD: 배출계수_드롭다운!$I$3:$I$6
Name DD_WASTE_UNIT: 배출계수_드롭다운!$J$3:$J$4

Sheet 기업정보
E1: 회사 목록(관리용)
B2: Scope 3 배출량 산정 템플릿 | E2: 공연공
B4: 기업 정보 입력
B5: - 아래에 적용 기업명을 선택하면, 각 카테고리 시트(C5 폐기물 종류 등) 상단의 '*적용 기업명' 칸과 상세명 자동 매칭에 함께 반영됩니다.
B7: *적용 기업명 | C7: 공연공 | D7: ※ 새 회사를 추가하려면 이 시트 E열에 회사명을 한 줄 추가한 뒤 여기서 선택하세요. 그 회사의 실제 매핑 데이터는 '회사별_폐기물매핑'·'회사별_교통수단매핑' 시트 A~C열에 별도로 추가해야 자동 매칭이 동작합니다.

Sheet C3_연료에너지
B2: C3. 연료 및 에너지 관련 활동
B4: 카테고리 정의
B5: - Scope 1, Scope 2에 포함되지 않은 연료 및 에너지의 업스트림 배출량과 송전·배전 손실에서 발생하는 온실가스 배출량
B6: - 직접 연소 배출량 또는 전력 사용 배출량 자체가 아니라 연료 생산·운송 및 전력 손실 등 간접 배출량에 해당
B9: 작성 기준
B10: 1) 온실가스 산정 식: Σ(연료/에너지 사용량 × 연료/에너지별 업스트림 또는 손실 배출계수)
B11: - 온실가스 배출계수는 환경부-환경성적표지(EPD) 평가계수를 활용
B12: 2) 원지출금액이 아니라 실제 사용량을 기준으로 작성
B13: 3) 연료/에너지명과 단위는 실제 사용한 항목 기준으로 선택
B14: 4) 동일한 연료라도 사업장, 단위, 사용 목적이 다르면 행을 나누어 작성
B16: ※ 사용 기준: 월별 자료가 있으면 1월~12월 칸에 입력하고, 연간 총량만 있으면 연간 입력 칸에 입력합니다. 동일 행에서 연간과 월별을 중복 입력하지 마세요.
B17: ※ 주황색으로 표시된 필수 입력칸은 반드시 작성해야 합니다.
B18: *국가 | C18: *사업장 | D18: *연료/에너지명 | E18: *단위 | F18: 연간 입력 | G18: 월별 사용량 | S18: 비고(선택) | T18: 배출계수(tCO2e/단위) | U18: 배출량(tCO2e)
F19: 연간사용량 | G19: 1월 | H19: 2월 | I19: 3월 | J19: 4월 | K19: 5월 | L19: 6월 | M19: 7월 | N19: 8월 | O19: 9월 | P19: 10월 | Q19: 11월 | R19: 12월
B20: 대한민국 | C20: 제주사옥 | D20: 전력 | E20: kWh | F20: 1204323.7
B21: 대한민국 | C21: 제주사옥 | D21: 도시가스(LNG) | E21: Nm³ | F21: 40420.502
B22: 대한민국 | C22: 서울상록회관 | D22: 전력 | E22: kWh | F22: 278632
B23: 대한민국 | C23: 서울상록회관 | D23: 도시가스(LNG) | E23: Nm³ | F23: 26542
B24: 대한민국 | C24: 대구지부 | D24: 전력 | E24: kWh | F24: 10612
B25: 대한민국 | C25: 천안상록리조트 | D25: 전력 | E25: kWh | F25: 5701487
B26: 대한민국 | C26: 천안상록리조트 | D26: 도시가스(LNG) | E26: Nm³ | F26: 622485
B27: 대한민국 | C27: 화성상록골프장 | D27: 전력 | E27: kWh | F27: 2120259
B28: 대한민국 | C28: 화성상록골프장 | D28: 실내 등유 | E28: L | F28: 156964 | S28: 부생연료1호
B29: 대한민국 | C29: 화성상록골프장 | D29: 액화석유가스(LPG) | E29: Nm³ | F29: 11358
B30: 대한민국 | C30: 화성상록골프장 | D30: 실내 등유 | E30: L | F30: 4200
B31: 대한민국 | C31: 남원상록골프장 | D31: 전력 | E31: kWh | F31: 689829
B32: 대한민국 | C32: 남원상록골프장 | D32: 액화석유가스(LPG) | E32: Nm³ | F32: 40949
B33: 대한민국 | C33: 남원상록골프장 | D33: 실내 등유 | E33: L | F33: 2399.77
B34: 대한민국 | C34: 김해상록골프장 | D34: 전력 | E34: kWh | F34: 1410420
B35: 대한민국 | C35: 김해상록골프장 | D35: 액화석유가스(LPG) | E35: Nm³ | F35: 20378
B36: 대한민국 | C36: 수안보상록호텔 | D36: 전력 | E36: kWh | F36: 1333943
B37: 대한민국 | C37: 수안보상록호텔 | D37: 경유 | E37: L | F37: 170145 | S37: 부생연료2호
B38: 대한민국 | C38: 제주본부(차량) | D38: 경유 | E38: L | F38: 7324.713
B39: 대한민국 | C39: 서울지부(차량) | D39: LPG(차량) | E39: L | F39: 178.118
B40: 대한민국 | C40: 세종대전지부(차량) | D40: 휘발유 | E40: L | F40: 279.8
B41: 대한민국 | C41: 광주전북지부(차량) | D41: 휘발유 | E41: L | F41: 434.321
B42: 대한민국 | C42: 천안상록리조트(차량) | D42: 경유 | E42: L | F42: 10998
B43: 대한민국 | C43: 천안상록리조트(차량) | D43: 휘발유 | E43: L | F43: 1849.878
B44: 대한민국 | C44: 화성상록골프장(차량) | D44: 경유 | E44: L | F44: 2278
B45: 대한민국 | C45: 화성상록골프장(차량) | D45: 휘발유 | E45: L | F45: 2982.996
...

Sheet C5_사업장폐기물
B2: C5. 사업장 발생 폐기물
B4: 카테고리 정의
B5: - 보고년도에 운영 과정에서 발생한 폐기물의 처리·반매립·소각 시 발생한 온실가스 배출량
B6: - 본사, 지부, 복지시설 운영 과정의 일반 폐기물, 음식물 쓰레기 등도 포함
B9: 작성 기준
B10: 1) 온실가스 산정 식: Σ(폐기물 발생량 × 처리방법별 배출계수)
B11: - 배출계수는 환경부 환경성적표지(EPD) 등 폐기물 처리 배출계수 활용
B12: 2) 상세 폐기물명은 실제 처리업체 자료, 올바로시스템 명칭 기준으로 작성
B13: 3) 동일한 폐기물이라도 처리방법이 다르면 행을 나누어 작성
B14: *적용 기업명 | C14: =기업정보!$C$7 -> 공연공 | D14: ※ 이 값은 '기업정보' 시트에서 선택한 적용 기업명이 자동으로 반영된 것입니다. 상세 폐기물명(E열) 입력 시 폐기물 종류(D열)가 '회사별_폐기물매핑' 매핑표를 기준으로 자동 매칭됩니다.
B15: ※ 사용 기준: 월별 자료가 있으면 1월~12월 칸에 입력하고, 연간 총량만 있으면 연간 입력 칸에 입력합니다. 동일 행에서 연간과 월별을 중복 입력하지 마세요.
B16: ※ 주황색으로 표시된 필수 입력칸은 반드시 작성해야 합니다.
B17: *국가 | C17: *사업장 | D17: *폐기물 종류 | E17: 상세 폐기물명(선택) | F17: *단위 | G17: *처리방법 | H17: 연간 입력 | I17: 월별 처리량 | U17: 비고(선택) | V17: 배출계수(tCO2e/단위) | W17: 배출량(tCO2e)
H18: 연간처리량 | I18: 1월 | J18: 2월 | K18: 3월 | L18: 4월 | M18: 5월 | N18: 6월 | O18: 7월 | P18: 8월 | Q18: 9월 | R18: 10월 | S18: 11월 | T18: 12월
B19: 대한민국 | C19: 본사 | D19: =IFERROR(INDEX(회사별_폐기물매핑!$C$2:$C$1000,MATCH(1,INDEX(($C$14=회사별_폐기물매핑!$A$2:$A$1000)*($E19=회사별_폐기물매핑!$B$2:$B$1000),0),0)),"") -> 기타 | E19: 일반쓰레기 | F19: ton | G19: 소각 | H19: 121.9
B20: 대한민국 | C20: 본사 | D20: =IFERROR(INDEX(회사별_폐기물매핑!$C$2:$C$1000,MATCH(1,INDEX(($C$14=회사별_폐기물매핑!$A$2:$A$1000)*($E20=회사별_폐기물매핑!$B$2:$B$1000),0),0)),"") -> 폐콘크리트류 | E20: 폐아스발트 | F20: ton | G20: 기타 | H20: 947.63 | U20: 파쇄
B21: 대한민국 | C21: 서울상록회관 | D21: =IFERROR(INDEX(회사별_폐기물매핑!$C$2:$C$1000,MATCH(1,INDEX(($C$14=회사별_폐기물매핑!$A$2:$A$1000)*($E21=회사별_폐기물매핑!$B$2:$B$1000),0),0)),"") -> 폐플라스틱류 | E21: 폐합성수지 | F21: ton | G21: 재활용 | H21: 89.3
B22: 대한민국 | C22: 서울상록회관 | D22: =IFERROR(INDEX(회사별_폐기물매핑!$C$2:$C$1000,MATCH(1,INDEX(($C$14=회사별_폐기물매핑!$A$2:$A$1000)*($E22=회사별_폐기물매핑!$B$2:$B$1000),0),0)),"") -> 기타 | E22: 폐산 | F22: ton | G22: 재활용 | H22: 6.31
B23: 대한민국 | C23: 천안상록리조트 | D23: =IFERROR(INDEX(회사별_폐기물매핑!$C$2:$C$1000,MATCH(1,INDEX(($C$14=회사별_폐기물매핑!$A$2:$A$1000)*($E23=회사별_폐기물매핑!$B$2:$B$1000),0),0)),"") -> 폐플라스틱류 | E23: 폐합성수지 | F23: ton | G23: 재활용 | H23: 277.88
B24: 대한민국 | C24: 천안상록리조트 | D24: =IFERROR(INDEX(회사별_폐기물매핑!$C$2:$C$1000,MATCH(1,INDEX(($C$14=회사별_폐기물매핑!$A$2:$A$1000)*($E24=회사별_폐기물매핑!$B$2:$B$1000),0),0)),"") -> 폐목재류 | E24: 임목폐기물 | F24: ton | G24: 재활용 | H24: 90.21
B25: 대한민국 | C25: 천안상록리조트 | D25: =IFERROR(INDEX(회사별_폐기물매핑!$C$2:$C$1000,MATCH(1,INDEX(($C$14=회사별_폐기물매핑!$A$2:$A$1000)*($E25=회사별_폐기물매핑!$B$2:$B$1000),0),0)),"") -> 기타 | E25: 잔디예지물 | F25: ton | G25: 재활용 | H25: 15.53
B26: 대한민국 | C26: 천안상록리조트 | D26: =IFERROR(INDEX(회사별_폐기물매핑!$C$2:$C$1000,MATCH(1,INDEX(($C$14=회사별_폐기물매핑!$A$2:$A$1000)*($E26=회사별_폐기물매핑!$B$2:$B$1000),0),0)),"") -> 기타 | E26: 폐토사 | F26: ton | G26: 재활용 | H26: 244.86
B27: 대한민국 | C27: 천안상록리조트 | D27: =IFERROR(INDEX(회사별_폐기물매핑!$C$2:$C$1000,MATCH(1,INDEX(($C$14=회사별_폐기물매핑!$A$2:$A$1000)*($E27=회사별_폐기물매핑!$B$2:$B$1000),0),0)),"") -> 폐유류 | E27: 액상 폐유 | F27: ton | G27: 재활용 | H27: 0.34
B28: 대한민국 | C28: 천안상록리조트 | D28: 음식물류 폐기물 | F28: ton | G28: 소각 | H28: 100
B29: 대한민국 | C29: 천안상록리조트 | D29: 폐지류 | F29: ton | G29: 소각 | H29: 50
B30: 대한민국 | C30: 화성상록골프장 | D30: 폐목재류 | F30: ton | G30: 소각 | H30: 2000
B31: 대한민국 | C31: 화성상록골프장 | D31: =IFERROR(INDEX(회사별_폐기물매핑!$C$2:$C$1000,MATCH(1,INDEX(($C$14=회사별_폐기물매핑!$A$2:$A$1000)*($E31=회사별_폐기물매핑!$B$2:$B$1000),0),0)),"") -> 폐플라스틱류 | E31: 폐합성수지 | F31: ton | G31: 재활용 | H31: 5.4
B32: 대한민국 | C32: 화성상록골프장 | D32: =IFERROR(INDEX(회사별_폐기물매핑!$C$2:$C$1000,MATCH(1,INDEX(($C$14=회사별_폐기물매핑!$A$2:$A$1000)*($E32=회사별_폐기물매핑!$B$2:$B$1000),0),0)),"") -> 폐목재류 | E32: 임목폐기물 | F32: ton | G32: 재활용 | H32: 21.74
B33: 대한민국 | C33: 화성상록골프장 | D33: =IFERROR(INDEX(회사별_폐기물매핑!$C$2:$C$1000,MATCH(1,INDEX(($C$14=회사별_폐기물매핑!$A$2:$A$1000)*($E33=회사별_폐기물매핑!$B$2:$B$1000),0),0)),"") -> 폐고무/피혁류 | E33: 폐타이어 | F33: ton | G33: 재활용 | H33: 0.77
B34: 대한민국 | C34: 화성상록골프장 | D34: =IFERROR(INDEX(회사별_폐기물매핑!$C$2:$C$1000,MATCH(1,INDEX(($C$14=회사별_폐기물매핑!$A$2:$A$1000)*($E34=회사별_폐기물매핑!$B$2:$B$1000),0),0)),"") -> 기타 | E34: 잔디예지물 | F34: ton | G34: 재활용 | H34: 14.52
B35: 대한민국 | C35: 화성상록골프장 | D35: =IFERROR(INDEX(회사별_폐기물매핑!$C$2:$C$1000,MATCH(1,INDEX(($C$14=회사별_폐기물매핑!$A$2:$A$1000)*($E35=회사별_폐기물매핑!$B$2:$B$1000),0),0)),"") -> 기타 | E35: 폐토사 | F35: ton | G35: 재활용 | H35: 13.7
B36: 대한민국 | C36: 화성상록골프장 | D36: =IFERROR(INDEX(회사별_폐기물매핑!$C$2:$C$1000,MATCH(1,INDEX(($C$14=회사별_폐기물매핑!$A$2:$A$1000)*($E36=회사별_폐기물매핑!$B$2:$B$1000),0),0)),"") -> 폐유류 | E36: 액상 폐유 | F36: ton | G36: 재활용 | H36: 0.6
B37: 대한민국 | C37: 화성상록골프장 | D37: =IFERROR(INDEX(회사별_폐기물매핑!$C$2:$C$1000,MATCH(1,INDEX(($C$14=회사별_폐기물매핑!$A$2:$A$1000)*($E37=회사별_폐기물매핑!$B$2:$B$1000),0),0)),"") -> 폐유류 | E37: 고상 폐유 | F37: ton | G37: 소각 | H37: 0.2
B38: 대한민국 | C38: 남원상록골프장 | D38: =IFERROR(INDEX(회사별_폐기물매핑!$C$2:$C$1000,MATCH(1,INDEX(($C$14=회사별_폐기물매핑!$A$2:$A$1000)*($E38=회사별_폐기물매핑!$B$2:$B$1000),0),0)),"") -> 기타 | E38: 일반쓰레기 | F38: ton | G38: 소각 | H38: 50
B39: 대한민국 | C39: 남원상록골프장 | D39: =IFERROR(INDEX(회사별_폐기물매핑!$C$2:$C$1000,MATCH(1,INDEX(($C$14=회사별_폐기물매핑!$A$2:$A$1000)*($E39=회사별_폐기물매핑!$B$2:$B$1000),0),0)),"") -> 기타 | E39: 잔디예지물 | F39: ton | G39: 재활용 | H39: 48
B40: 대한민국 | C40: 남원상록골프장 | D40: =IFERROR(INDEX(회사별_폐기물매핑!$C$2:$C$1000,MATCH(1,INDEX(($C$14=회사별_폐기물매핑!$A$2:$A$1000)*($E40=회사별_폐기물매핑!$B$2:$B$1000),0),0)),"") -> 폐유류 | E40: 액상 폐유 | F40: ton | G40: 재활용 | H40: 0.6
B41: 대한민국 | C41: 남원상록골프장 | D41: =IFERROR(INDEX(회사별_폐기물매핑!$C$2:$C$1000,MATCH(1,INDEX(($C$14=회사별_폐기물매핑!$A$2:$A$1000)*($E41=회사별_폐기물매핑!$B$2:$B$1000),0),0)),"") -> 폐유류 | E41: 고상 폐유 | F41: ton | G41: 소각 | H41: 0.2
B42: 대한민국 | C42: 남원상록골프장 | D42: =IFERROR(INDEX(회사별_폐기물매핑!$C$2:$C$1000,MATCH(1,INDEX(($C$14=회사별_폐기물매핑!$A$2:$A$1000)*($E42=회사별_폐기물매핑!$B$2:$B$1000),0),0)),"") -> 지정폐기물 | E42: 폐농약병 | F42: ton | G42: 재활용 | H42: 0.199
... B50: 대한민국 | C50: 수안보상록호텔 | D50: =IFERROR(INDEX(회사별_폐기물매핑!$C$2:$C$1000,MATCH(1,INDEX(($C$14=회사별_폐기물매핑!$A$2:$A$1000)*($E50=회사별_폐기물매핑!$B$2:$B$1000),0),0)),"") -> 폐플라스틱류 | E50: 폐합성수지 | F50: ton | G50: 재활용 | H50: 3.51
D51: =IFERROR(INDEX(회사별_폐기물매핑!$C$2:$C$1000,MATCH(1,INDEX(($C$14=회사별_폐기물매핑!$A$2:$A$1000)*($E51=회사별_폐기물매핑!$B$2:$B$1000),0),0)),"")
...

Sheet 배출계수_드롭다운
A1: DD_PURCHASE_GROUP | B1: DD_ENERGY | C1: DD_ENERGY_UNIT | D1: DD_TRANSPORT_DISTANCE | E1: DD_TRANSPORT_SPEND | F1: DD_TRAVEL_DISTANCE | G1: DD_TRAVEL_SPEND | H1: DD_WASTE_C5_TYPE | I1: DD_WASTE_METHOD | J1: DD_WASTE_UNIT | K1: DD_TRANSPORT_WEIGHT_UNIT | M1: C6/C7 거리기반 상세 매핑
A2: C1/C2 구매·자본재 품목군 | B2: C3/C8/C11/C13/C14 에너지명 | C2: 에너지 기준단위 | D2: C4/C9 거리기반 운송수단 | E2: C4/C9 금액기반 운송항목 | F2: C6/C7 거리기반 교통수단 | G2: C6 금액기반 출장항목 | H2: C5 폐기물 종류 | I2: 폐기물 처리방법 | J2: 폐기물 중량단위 | K2: 운송 중량단위 | M2: 표시값(드롭다운) | N2: 표준코드 | O2: DEFRA Type | P2: 매핑 키워드
A3: 원재료/부자재 | B3: 도시가스(LNG) | C3: kWh | D3: 도로 운송 (일반화물트럭) | E3: 항공 운송(여객·화물·전세) | F3: 항공(국제선 평균) | G3: 항공권(여객·전세) | H3: 음식물류 폐기물 | I3: 매립 | J3: kg | K3: kg | M3: 항공(국제선 평균) | N3: flight | O3: International, non-UK - Average passenger | P3: 항공,비행기,비행,airplane,flight,국제선,해외출장
A4: 포장재 | B4: 천연가스(LNG) | C4: GJ | D4: 도로 운송 (택배·소화물) | E4: 철도 운송 | F4: 국내선 항공 | G4: 택시·리무진 비용 | H4: 폐지류 | I4: 소각 | J4: ton | K4: ton | M4: 국내선 항공 | N4: flight_dom | O4: Domestic, to/from UK - Average | P4: 국내선,국내항공,국내비행,domestic
A5: 사무용품 | B5: CNG(차량) | C5: L | D5: 철도 운송 | E5: 해상 운송(원양) | F5: 페리 | G5: 시외버스·고속버스 요금 | H5: 폐플라스틱류 | I5: 재활용 | M5: 페리 | N5: ferry | O5: Average (all passenger) | P5: 페리,ferry,선박,배
A6: 탕비·식음료 | B6: LNG(차량) | C6: kg | D6: 해상 운송 (컨테이너선) | E6: 내륙 수로 화물 | F6: 버스 | G6: 기차·KTX 요금 | H6: 폐목재류 | I6: 기타 | M6: 버스 | N6: bus | O6: Average local bus | P6: 버스,bus,고속버스,시외버스,시내버스,광역버스,전세버스,셔틀
A7: IT장비 | B7: LPG(차량) | C7: Nm³ | D7: 해상 운송 (벌크선) | E7: 화물 트럭(지역·이사) | F7: 장거리버스/코치 | G7: 렌터카·렌트 트럭 | H7: 폐섬유류 | M7: 장거리버스/코치 | N7: coach | O7: Coach | P7: 코치,장거리버스,express bus
A8: 사무가구·비품 | B8: 도시가스(LPG) | D8: 항공 운송 | E8: 장거리 화물 트럭 (차량단위) | F8: 철도/KTX/SRT | G8: 숙박비(호텔·게스트하우스 등) | H8: 폐유리류 | M8: 철도/KTX/SRT | N8: train | O8: National rail | P8: 기차,KTX,SRT,ITX,새마을,무궁화,열차,철도
A9: 시설·유지보수 | B9: 액화석유가스(LPG) | D9: 내륙수로 운송 | E9: 장거리 화물 트럭 (혼재) | F9: 지하철/도시철도 | H9: 폐금속류 | M9: 지하철/도시철도 | N9: subway | O9: London Underground / Metro | P9: 지하철,subway,metro,전철,도시철도
A10: 외주·서비스 | B10: 경유 | E10: 특수화물 트럭 (장거리) | F10: 택시 | H10: 오니류 | M10: 택시 | N10: taxi | O10: Regular taxi | P10: 택시,taxi,cab,카카오t,카카오택시,우버,uber
A11: 에너지·유틸리티 | B11: 보일러 등유 | E11: 복합 대중교통 | F11: 승용차(평균) | H11: 폐전기전자제품 | M11: 승용차(평균) | N11: car | O11: Average car | P11: 승용차,자가용,car,차량,렌터카,자동차
A12: 차량·운송장비 | B12: 실내 등유 | E12: 버스(대중교통·통근·전세) | F12: 하이브리드차 | H12: 폐배터리 | M12: 하이브리드차 | N12: car_hybrid | O12: PHEV - Method 2 | P12: 하이브리드,hybrid,HEV,PHEV,플러그인하이브리드
A13: 생산설비 | B13: 항공유 | E13: 기타 도시교통 | F13: 전기차 | H13: 폐유류 | M13: 전기차 | N13: car_ev | O13: BEV | P13: 전기차,전기자동차,EV,BEV,테슬라,아이오닉,EV6
A14: 안전·위생 | B14: 휘발유 | E14: 도시간·농촌 버스 | F14: 오토바이 | H14: 폐콘크리트류 | M14: 오토바이 | N14: motorcycle | O14: Average | P14: 오토바이,motorcycle,바이크
A15: 건설자재 | B15: 전력 | E15: 택시·리무진 | F15: 도보/자전거 | H15: 폐고무/피혁류 | M15: 도보/자전거 | N15: walk | O15: 도보·자전거 | P15: 도보,자전거,walk,bicycle,bike
A16: 통신·미디어 | B16: 열(스팀) | E16: 원유 파이프라인 | H16: 지정폐기물
A17: 여행·숙박 | B17: 선택안함 | E17: 화물운송 주선 (포워딩) | H17: 기타
A18: 기타 | E18: 택배·퀵배송 | H18: [전체 평균]
A19: 선택안함 | E19: 지역 배달
A38: ※ 본 시트의 드롭다운 목록은 업로드된 「배출계수_통합_DB」의 각 시트 값을 기준으로 생성했습니다. 템플릿의 입력값과 DB 기준명이 다른 경우에는 「드롭다운_매핑검토」의 매핑표를 참고하세요.

Sheet 드롭다운_매핑검토
A1: 구분 | B1: 템플릿 시트/범위 | C1: 기존 드롭다운/예시값 | D1: DB 기준 변경값 | E1: 조치
A2: 구매/자본재 | B2: C1 D20:D219, C2 D20:D219 | C2: 기존 품목군/자산분류 일부 | D2: 구매_USEPA!품목군 기준 | E2: DB 품목군으로 통일
A3: 에너지 | B3: C3/C8/C11/C13/C14 에너지명 | C3: 전기, 스팀, LPG 등 | D3: 에너지!활동유형(에너지원) 기준 | E3: 전기→전력, 스팀→열(스팀), LPG→액화석유가스(LPG) 등 매핑
A4: 에너지 단위 | B4: 에너지 단위 컬럼 | C4: m3, Nm3 등 | D4: 에너지!투입량 기준단위 기준 | E4: Nm³ 등 DB 표기 통일
A5: 운송 거리기반 | B5: C4-1/C9-1 운송수단 | C5: 도로/해상/항공/철도 | D5: 운송!운송수단(EPD 원본명) 기준 | E5: 세부 EF 단위로 상세화 및 내륙수로 추가
A6: 운송 금액기반 | B6: C4-2/C9-2 운송수단 | C6: 도로/해상/항공/철도 | D6: 운송_Spend!한국어 품목명 기준 | E6: 화물트럭 운송, 정기 항공화물 등으로 상세화 → 이후 배출계수(EF)가 완전히 동일한 항목끼리 재통합 (27→17개, 배출계수_통합_DB.xlsx의 운송_Spend 시트도 동일 기준으로 병합)
A7: 출장/통근 거리기반 | B7: C6-1/C7 교통수단 | C7: 자동차, 철도(KTX/SRT) 등 | D7: 출장_통근!표준코드/키워드 기준 | E7: DB 표준코드와 연결되는 한국어 표시값으로 정리 → 실사용 데이터(공연공 실적 1,200여 행) 기준 33개 중 실제로 쓰인 건 9개뿐이라, 좌석등급·차량크기 등 세부 구분(비즈니스/이코노미, 소형/중형/대형 등)을 13개로 축소(파이프라인 TRAVEL_EF_MAP의 세부 EF 코드 자체는 그대로 보존, 드롭다운만 정리)
A8: 출장비 | B8: C6-2 출장항목 | C8: 항공/철도/택시/렌터카/숙박/기타 | D8: 출장_Spend!한국어 품목명 기준 | E8: 여객 항공권, 기차·KTX 요금 등으로 상세화 → EF가 동일한 항목 병합 + 식비/통신비(DB에 배출계수 없음) 제거로 14→6개 축소, 배출계수_통합_DB.xlsx의 출장_Spend 시트도 동일 기준으로 병합
A9: 사업장폐기물 | B9: C5 폐기물종류/처리방법 | C9: 템플릿 임의목록 | D9: 폐기물_C5 기준 | E9: DB에 없는 항목은 지정폐기물/기타 등으로 매핑
A10: 판매제품폐기 | B10: C12 대/중/소분류 | C10: 기존 전체 법정 분류 목록 | D10: 폐기물_C12에 계수 있는 항목만 | E10: 소분류까지 DB 보유 항목 중심으로 축소·재구성
A11: 회사별 자동매칭 | B11: C5 폐기물종류 / C6-1·C7 교통수단 | C11: (신규 기능) | D11: '회사별_폐기물매핑'/'회사별_교통수단매핑' 시트 | E11: 표지(기업정보)에서 회사 선택 → 상세명(E열/Y열) 입력 시 표준값이 자동 매칭되는 수식 추가. 회사 목록은 '기업정보' 시트 E열에서 관리하고, 두 매핑 시트는 그 값을 그대로 참조
A12: 항공 거리계산(C6-1/C7) | B12: get_distance_km(mode="air") | C12: 주소 기준 직선거리 × 1.05 | D12: Climatiq/ICAO/DEFRA 벤치마킹 결과 | E12: 출도착지가 공항이 아니라 주소·지명이면 AI가 그 지역의 가까운 주요 공항으로 치환한 뒤 공항-공항 간 거리로 계산하도록 수정, 우회보정 계수도 1.05 → 1.09로 상향
A13: 주요 기존값 → DB 기준값 매핑
A14: 매핑그룹 | B14: 기존값 | C14: DB 기준값
A15: purchase_group | B15: 원재료 | C15: 원재료/부자재
A16: purchase_group | B16: 부자재 | C16: 원재료/부자재
A17: purchase_group | B17: 종이/인쇄물 | C17: 사무용품
A18: purchase_group | B18: IT/전자장비 | C18: IT장비
A19: purchase_group | B19: 소모품 | C19: 사무용품
A20: purchase_group | B20: 화학물질 | C20: 원재료/부자재
A21: purchase_group | B21: 금속/철강 | C21: 원재료/부자재
A22: purchase_group | B22: 플라스틱/고무 | C22: 원재료/부자재
A23: purchase_group | B23: 섬유/의류 | C23: 원재료/부자재
A24: purchase_group | B24: 식음료 | C24: 탕비·식음료
A25: purchase_group | B25: 운송/물류서비스 | C25: 외주·서비스
... A134: unit | B134: MJ | C134: MJ

Sheet 회사별_폐기물매핑
A1: 회사명 | B1: 상세 폐기물명 | C1: 폐기물 종류 | E1: 회사 목록(드롭다운용) | G1: 회사 목록은 이 시트가 아니라 '기업정보' 시트의 E열에서 관리합니다(이 시트 E열은 그 값을 그대로 표시). 새 회사를 추가하려면: ① 이 시트 A~C열에 그 회사의 '상세 폐기물명 → 폐기물 종류' 행을 추가하고 ② '기업정보' 시트 E열에 회사명을 한 줄 추가하세요.
A2: 공연공 | B2: 일반쓰레기 | C2: 기타 | E2: =IF(기업정보!E2="","",기업정보!E2) -> 공연공
A3: 공연공 | B3: 폐아스발트 | C3: 폐콘크리트류 | E3: =IF(기업정보!E3="","",기업정보!E3)
A4: 공연공 | B4: 폐합성수지 | C4: 폐플라스틱류 | E4: =IF(기업정보!E4="","",기업정보!E4)
A5: 공연공 | B5: 폐산 | C5: 기타 | E5: =IF(기업정보!E5="","",기업정보!E5)
A6: 공연공 | B6: 임목폐기물 | C6: 폐목재류 | E6: =IF(기업정보!E6="","",기업정보!E6)
A7: 공연공 | B7: 잔디예지물 | C7: 기타 | E7: =IF(기업정보!E7="","",기업정보!E7)
A8: 공연공 | B8: 폐토사 | C8: 기타 | E8: =IF(기업정보!E8="","",기업정보!E8)
A9: 공연공 | B9: 액상 폐유 | C9: 폐유류 | E9: =IF(기업정보!E9="","",기업정보!E9)
A10: 공연공 | B10: 고상 폐유 | C10: 폐유류 | E10: =IF(기업정보!E10="","",기업정보!E10)
A11: 공연공 | B11: 폐농약병 | C11: 지정폐기물 | E11: =IF(기업정보!E11="","",기업정보!E11)
A12: 공연공 | B12: 폐타이어 | C12: 폐고무/피혁류 | E12: =IF(기업정보!E12="","",기업정보!E12)
A13: 공연공 | B13: 기타 | C13: 기타 | E13: =IF(기업정보!E13="","",기업정보!E13)
... A15: 공연공 | B15: 불연성생활쓰레기 | C15: 기타 | E15: =IF(기업정보!E15="","",기업정보!E15)
E16: =IF(기업정보!E16="","",기업정보!E16)
E17: =IF(기업정보!E17="","",기업정보!E17)
E18: =IF(기업정보!E18="","",기업정보!E18)
E19: =IF(기업정보!E19="","",기업정보!E19)
E20: =IF(기업정보!E20="","",기업정보!E20)
E21: =IF(기업정보!E21="","",기업정보!E21)
E22: =IF(기업정보!E22="","",기업정보!E22)
E23: =IF(기업정보!E23="","",기업정보!E23)
E24: =IF(기업정보!E24="","",기업정보!E24)
E25: =IF(기업정보!E25="","",기업정보!E25)
E26: =IF(기업정보!E26="","",기업정보!E26)
E27: =IF(기업정보!E27="","",기업정보!E27)
... E50: =IF(기업정보!E50="","",기업정보!E50)

Sheet 회사별_교통수단매핑
A1: 회사명 | B1: 상세 교통수단명 | C1: 표준 교통수단 | E1: 회사 목록(드롭다운용) | G1: 회사 목록은 이 시트가 아니라 '기업정보' 시트의 E열에서 관리합니다(이 시트 E열은 그 값을 그대로 표시). 새 회사를 추가하려면: ① 이 시트 A~C열에 그 회사의 '상세 교통수단명 → 표준 교통수단' 행을 추가하고 ② '기업정보' 시트 E열에 회사명을 한 줄 추가하세요. 표준 교통수단은 반드시 '배출계수_드롭다운' 시트 F열(DD_TRAVEL_DISTANCE) 목록 값과 똑같이 입력해야 합니다.
E2: =IF(기업정보!E2="","",기업정보!E2) -> 공연공
E3: =IF(기업정보!E3="","",기업정보!E3)
E4: =IF(기업정보!E4="","",기업정보!E4)
E5: =IF(기업정보!E5="","",기업정보!E5)
E6: =IF(기업정보!E6="","",기업정보!E6)
E7: =IF(기업정보!E7="","",기업정보!E7)
E8: =IF(기업정보!E8="","",기업정보!E8)
E9: =IF(기업정보!E9="","",기업정보!E9)
E10: =IF(기업정보!E10="","",기업정보!E10)
E11: =IF(기업정보!E11="","",기업정보!E11)
E12: =IF(기업정보!E12="","",기업정보!E12)
E13: =IF(기업정보!E13="","",기업정보!E13)
... E50: =IF(기업정보!E50="","",기업정보!E50)
