Workbook
Name DD_APPLIED_COMPANY: 기업정보!$E$2:$E$50
Name DD_ENERGY: 배출계수_드롭다운!$B$3:$B$16
Name DD_ENERGY_UNIT: 배출계수_드롭다운!$C$3:$C$7
Name DD_PURCHASE_GROUP: 배출계수_드롭다운!$A$3:$A$19
Name DD_TRANSPORT_DISTANCE: 배출계수_드롭다운!$D$3:$D$9
Name DD_TRANSPORT_SPEND: 배출계수_드롭다운!$E$3:$E$19
Name DD_TRANSPORT_WEIGHT_UNIT: 배출계수_드롭다운!$K$3:$K$4
Name DD_TRAVEL_DISTANCE: 배출계수_드롭다운!$F$3:$F$15
Name DD_TRAVEL_SPEND: 배출계수_드롭다운!$G$3:$G$8
Name DD_WASTE_C5_TYPE: 배출계수_드롭다운!$H$3:$H$18
Name DD_WASTE_METHOD: 배출계수_드롭다운!$I$3:$I$6
Name DD_WASTE_UNIT: 배출계수_드롭다운!$J$3:$J$4

Sheet 기업정보
E1: 회사 목록(관리용)
B2: Scope 3 배출량 산정 템플릿 | E2: 공연공
B4: 기업 정보 입력
B5: - 아래에 적용 기업명을 선택하면, 각 카테고리 시트(C5 폐기물 종류 등) 상단의 '*적용 기업명' 칸과 상세명 자동 매칭에 함께 반영됩니다.
B7: *적용 기업명 | C7: 공연공 | D7: ※ 새 회사를 추가하려면 이 시트 E열에 회사명을 한 줄 추가한 뒤 여기서 선택하세요. 그 회사의 실제 매핑 데이터는 '회사별_폐기물매핑'·'회사별_교통수단매핑' 시트 A~C열에 별도로 추가해야 자동 매칭이 동작합니다.

Sheet C6-1_출장거리
B2: C6. 임직원 출장 1안. 이동거리 기반
B4: 카테고리 정의
B5: - 보고년도에 임직원 업무 출장 시 항공, 철도, 차량 등 교통수단 이용으로 발생한 온실가스 배출량
B6: - 출발지와 도착지 또는 이동거리를 알고 있는 출장에 적용
B9: 작성 기준
B10: 1) 온실가스 산정 식: Σ(왕복 이동거리 × 교통수단별 배출계수 × 인원수 × 이동횟수)
B11: - 온실가스 배출계수는 UK defra 평가계수를 활용 (*UK Government GHG Conversion Factor )
B12: 2) 편도거리나 출도착지 둘 중 하나는 반드시 작성(노란 박스) / 항공을 이용한 경우 출도착지는 도시명·주소 대신 공항명(예: 인천국제공항)으로 작성 권장 - 미기재 시 AI가 가까운 주요 공항으로 추정해 거리를 계산합니다(주소 기준으로 바로 계산하면 실제 항공 이동거리와 달라질 수 있음)
B13: 3) 숙박비와 교통비 지출금액만 아는 경우 C6-2 시트에 작성
B14: *적용 기업명 | C14: =기업정보!$C$7 -> 공연공
B15: ※ '기업정보' 시트에서 선택한 적용 기업명이 자동 반영됩니다. 상세 교통수단명(Y열) 입력 시 *교통수단(D열)이 '회사별_교통수단매핑' 매핑표를 기준으로 자동 매칭됩니다.
B16: ※ 사용 기준: 월별 자료가 있으면 1월~12월 칸에 입력하고, 연간 총량만 있으면 연간 입력 칸에 입력합니다. 동일 행에서 연간과 월별을 중복 입력하지 마세요.
B17: ※ 주황색으로 표시된 필수 입력칸은 반드시 작성해야 합니다.
B18: ※ 회색으로 표시된 입력란(배출계수, 배출량)은 자동으로 산출되므로 별도로 입력하지 않으셔도 됩니다.
B19: *국가 | C19: *출장주체 | D19: *교통수단 | E19: *인원수 | F19: 출도착지 | I19: 연간 입력 | J19: 월별 이동횟수 | V19: 비고(선택) | W19: 배출계수(tCO2e/km) | X19: 배출량(tCO2e) | Y19: 상세 교통수단명(선택)
F20: 출발지 | G20: 도착지 | H20: 편도거리(km)(선택) | I20: 연간이동횟수 | J20: 1월 | K20: 2월 | L20: 3월 | M20: 4월 | N20: 5월 | O20: 6월 | P20: 7월 | Q20: 8월 | R20: 9월 | S20: 10월 | T20: 11월 | U20: 12월
B21: 대한민국 | C21: 광주전북지부 | D21: =IFERROR(INDEX(회사별_교통수단매핑!$C$2:$C$1000,MATCH(1,INDEX(($C$14=회사별_교통수단매핑!$A$2:$A$1000)*($Y21=회사별_교통수단매핑!$B$2:$B$1000),0),0)),"") -> 장거리버스/코치 | E21: 1 | F21: 광주광역시 서구 죽봉대로 52 | G21: 경남 의령군 가례면 가례로 677 | I21: =IF(SUM(J21:U21)=0,"",SUM(J21:U21)) -> 1 | K21: 1 | W21: 0.00010385 | X21: 0.035523329 | Y21: 고속버스
B22: 대한민국 | C22: 광주전북지부 | D22: =IFERROR(INDEX(회사별_교통수단매핑!$C$2:$C$1000,MATCH(1,INDEX(($C$14=회사별_교통수단매핑!$A$2:$A$1000)*($Y22=회사별_교통수단매핑!$B$2:$B$1000),0),0)),"") -> 장거리버스/코치 | E22: 1 | F22: 광주광역시 서구 죽봉대로 53 | G22: 경북 영주시 봉현면 테라피로 209 | I22: =IF(SUM(J22:U22)=0,"",SUM(J22:U22)) -> 1 | S22: 1 | W22: 0.00010385 | X22: 0.065955569 | Y22: 고속버스
B23: 대한민국 | C23: 광주전북지부 | D23: =IFERROR(INDEX(회사별_교통수단매핑!$C$2:$C$1000,MATCH(1,INDEX(($C$14=회사별_교통수단매핑!$A$2:$A$1000)*($Y23=회사별_교통수단매핑!$B$2:$B$1000),0),0)),"") -> 장거리버스/코치 | E23: 1 | F23: 광주광역시 서구 죽봉대로 54 | G23: 서울특별시 강남구 언주로 508 | I23: =IF(SUM(J23:U23)=0,"",SUM(J23:U23)) -> 2 | U23: 2 | W23: 0.00010385 | X23: 0.14464506 | Y23: 고속버스
B24: 대한민국 | C24: 광주전북지부 | D24: =IFERROR(INDEX(회사별_교통수단매핑!$C$2:$C$1000,MATCH(1,INDEX(($C$14=회사별_교통수단매핑!$A$2:$A$1000)*($Y24=회사별_교통수단매핑!$B$2:$B$1000),0),0)),"") -> 장거리버스/코치 | E24: 1 | F24: 광주광역시 서구 죽봉대로 55 | G24: 전남 강진군 도암면 다산인재길 10 | I24: =IF(SUM(J24:U24)=0,"",SUM(J24:U24)) -> 7 | L24: 1 | M24: 1 | N24: 1 | O24: 1 | R24: 1 | S24: 1 | T24: 1 | W24: 0.00010385 | X24: 0.10831511 | Y24: 고속버스
B25: 대한민국 | C25: 광주전북지부 | D25: =IFERROR(INDEX(회사별_교통수단매핑!$C$2:$C$1000,MATCH(1,INDEX(($C$14=회사별_교통수단매핑!$A$2:$A$1000)*($Y25=회사별_교통수단매핑!$B$2:$B$1000),0),0)),"") -> 장거리버스/코치 | E25: 1 | F25: 광주광역시 서구 죽봉대로 56 | G25: 전남 나주시 경현동 | I25: =IF(SUM(J25:U25)=0,"",SUM(J25:U25)) -> 3 | R25: 1 | S25: 1 | T25: 1 | W25: 0.00010385 | X25: 0.015376866 | Y25: 고속버스
B26: 대한민국 | C26: 광주전북지부 | D26: =IFERROR(INDEX(회사별_교통수단매핑!$C$2:$C$1000,MATCH(1,INDEX(($C$14=회사별_교통수단매핑!$A$2:$A$1000)*($Y26=회사별_교통수단매핑!$B$2:$B$1000),0),0)),"") -> 장거리버스/코치 | E26: 1 | F26: 광주광역시 서구 죽봉대로 57 | G26: 전남 무안군 삼향읍 어진누리길 10 | I26: =IF(SUM(J26:U26)=0,"",SUM(J26:U26)) -> 1 | K26: 1 | W26: 0.00010385 | X26: 0.0096378534 | Y26: 고속버스
B27: 대한민국 | C27: 광주전북지부 | D27: =IFERROR(INDEX(회사별_교통수단매핑!$C$2:$C$1000,MATCH(1,INDEX(($C$14=회사별_교통수단매핑!$A$2:$A$1000)*($Y27=회사별_교통수단매핑!$B$2:$B$1000),0),0)),"") -> 장거리버스/코치 | E27: 1 | F27: 광주광역시 서구 죽봉대로 58 | G27: 전남 영암군 삼호읍 대불로 91 | I27: =IF(SUM(J27:U27)=0,"",SUM(J27:U27)) -> 1 | O27: 1 | W27: 0.00010385 | X27: 0.011154295 | Y27: 고속버스
B28: 대한민국 | C28: 광주전북지부 | D28: =IFERROR(INDEX(회사별_교통수단매핑!$C$2:$C$1000,MATCH(1,INDEX(($C$14=회사별_교통수단매핑!$A$2:$A$1000)*($Y28=회사별_교통수단매핑!$B$2:$B$1000),0),0)),"") -> 장거리버스/코치 | E28: 1 | F28: 광주광역시 서구 죽봉대로 59 | G28: 전남 장흥군 장흥읍 평화우산길 212-43 | I28: =IF(SUM(J28:U28)=0,"",SUM(J28:U28)) -> 1 | S28: 1 | W28: 0.00010385 | X28: 0.014341922 | Y28: 고속버스
B29: 대한민국 | C29: 광주전북지부 | D29: =IFERROR(INDEX(회사별_교통수단매핑!$C$2:$C$1000,MATCH(1,INDEX(($C$14=회사별_교통수단매핑!$A$2:$A$1000)*($Y29=회사별_교통수단매핑!$B$2:$B$1000),0),0)),"") -> 장거리버스/코치 | E29: 1 | F29: 광주광역시 서구 죽봉대로 60 | G29: 전라북도 전주시 완산구 평화동2가 | I29: =IF(SUM(J29:U29)=0,"",SUM(J29:U29)) -> 10 | J29: 1 | K29: 2 | M29: 4 | N29: 1 | O29: 1 | R29: 1 | W29: 0.00010385 | X29: 0.21461329 | Y29: 고속버스
B30: 대한민국 | C30: 광주전북지부 | D30: =IFERROR(INDEX(회사별_교통수단매핑!$C$2:$C$1000,MATCH(1,INDEX(($C$14=회사별_교통수단매핑!$A$2:$A$1000)*($Y30=회사별_교통수단매핑!$B$2:$B$1000),0),0)),"") -> 장거리버스/코치 | E30: 1 | F30: 광주광역시 서구 죽봉대로 61 | G30: 전북 고창군 고창읍 석정2로 179 | I30: =IF(SUM(J30:U30)=0,"",SUM(J30:U30)) -> 3 | P30: 2 | T30: 1 | W30: 0.00010385 | X30: 0.026860142 | Y30: 고속버스
B31: 대한민국 | C31: 광주전북지부 | D31: =IFERROR(INDEX(회사별_교통수단매핑!$C$2:$C$1000,MATCH(1,INDEX(($C$14=회사별_교통수단매핑!$A$2:$A$1000)*($Y31=회사별_교통수단매핑!$B$2:$B$1000),0),0)),"") -> 장거리버스/코치 | E31: 1 | F31: 광주광역시 서구 죽봉대로 62 | G31: 전북 남원시 동충동 | I31: =IF(SUM(J31:U31)=0,"",SUM(J31:U31)) -> 1 | O31: 1 | W31: 0.00010385 | X31: 0.01580878 | Y31: 고속버스
B32: 대한민국 | C32: 광주전북지부 | D32: =IFERROR(INDEX(회사별_교통수단매핑!$C$2:$C$1000,MATCH(1,INDEX(($C$14=회사별_교통수단매핑!$A$2:$A$1000)*($Y32=회사별_교통수단매핑!$B$2:$B$1000),0),0)),"") -> 장거리버스/코치 | E32: 1 | F32: 광주광역시 서구 죽봉대로 63 | G32: 전북 부안군 변산면 변산로 2060 | I32: =IF(SUM(J32:U32)=0,"",SUM(J32:U32)) -> 6 | N32: 3 | S32: 2 | T32: 1 | W32: 0.00010385 | X32: 0.10449891 | Y32: 고속버스
B33: 대한민국 | C33: 광주전북지부 | D33: =IFERROR(INDEX(회사별_교통수단매핑!$C$2:$C$1000,MATCH(1,INDEX(($C$14=회사별_교통수단매핑!$A$2:$A$1000)*($Y33=회사별_교통수단매핑!$B$2:$B$1000),0),0)),"") -> 장거리버스/코치 | E33: 1 | F33: 광주광역시 서구 죽봉대로 64 | G33: 전북 전주시 | I33: =IF(SUM(J33:U33)=0,"",SUM(J33:U33)) -> 1 | S33: 1 | W33: 0.00010385 | X33: 0.021461329 | Y33: 고속버스
B34: 대한민국 | C34: 광주전북지부 | D34: =IFERROR(INDEX(회사별_교통수단매핑!$C$2:$C$1000,MATCH(1,INDEX(($C$14=회사별_교통수단매핑!$A$2:$A$1000)*($Y34=회사별_교통수단매핑!$B$2:$B$1000),0),0)),"") -> 장거리버스/코치 | E34: 1 | F34: 광주광역시 서구 죽봉대로 65 | G34: 전북 전주시 덕진구 | I34: =IF(SUM(J34:U34)=0,"",SUM(J34:U34)) -> 2 | M34: 2 | W34: 0.00010385 | X34: 0.042922657 | Y34: 고속버스
B35: 대한민국 | C35: 광주전북지부 | D35: =IFERROR(INDEX(회사별_교통수단매핑!$C$2:$C$1000,MATCH(1,INDEX(($C$14=회사별_교통수단매핑!$A$2:$A$1000)*($Y35=회사별_교통수단매핑!$B$2:$B$1000),0),0)),"") -> 장거리버스/코치 | E35: 1 | F35: 광주광역시 서구 죽봉대로 66 | G35: 전북 전주시 덕진구 들사평로 38 | I35: =IF(SUM(J35:U35)=0,"",SUM(J35:U35)) -> 1 | N35: 1 | W35: 0.00010385 | X35: 0.021461329 | Y35: 고속버스
B36: 대한민국 | C36: 광주전북지부 | D36: =IFERROR(INDEX(회사별_교통수단매핑!$C$2:$C$1000,MATCH(1,INDEX(($C$14=회사별_교통수단매핑!$A$2:$A$1000)*($Y36=회사별_교통수단매핑!$B$2:$B$1000),0),0)),"") -> 장거리버스/코치 | E36: 1 | F36: 광주광역시 서구 죽봉대로 67 | G36: 전북 전주시 덕진구 중동 772-408 | I36: =IF(SUM(J36:U36)=0,"",SUM(J36:U36)) -> 8 | M36: 3 | O36: 1 | R36: 2 | T36: 2 | W36: 0.00010385 | X36: 0.17169063 | Y36: 고속버스
B37: 대한민국 | C37: 광주전북지부 | D37: =IFERROR(INDEX(회사별_교통수단매핑!$C$2:$C$1000,MATCH(1,INDEX(($C$14=회사별_교통수단매핑!$A$2:$A$1000)*($Y37=회사별_교통수단매핑!$B$2:$B$1000),0),0)),"") -> 장거리버스/코치 | E37: 1 | F37: 광주광역시 서구 죽봉대로 68 | G37: 전북 전주시 덕진구 팔복동1가 49-3 | I37: =IF(SUM(J37:U37)=0,"",SUM(J37:U37)) -> 1 | J37: 1 | W37: 0.00010385 | X37: 0.021461329 | Y37: 고속버스
B38: 대한민국 | C38: 광주전북지부 | D38: =IFERROR(INDEX(회사별_교통수단매핑!$C$2:$C$1000,MATCH(1,INDEX(($C$14=회사별_교통수단매핑!$A$2:$A$1000)*($Y38=회사별_교통수단매핑!$B$2:$B$1000),0),0)),"") -> 장거리버스/코치 | E38: 1 | F38: 광주광역시 서구 죽봉대로 69 | G38: 전북 전주시 완산구 낙수정2길 92 | I38: =IF(SUM(J38:U38)=0,"",SUM(J38:U38)) -> 1 | O38: 1 | W38: 0.00010385 | X38: 0.021461329 | Y38: 고속버스
B39: 대한민국 | C39: 광주전북지부 | D39: =IFERROR(INDEX(회사별_교통수단매핑!$C$2:$C$1000,MATCH(1,INDEX(($C$14=회사별_교통수단매핑!$A$2:$A$1000)*($Y39=회사별_교통수단매핑!$B$2:$B$1000),0),0)),"") -> 장거리버스/코치 | E39: 1 | F39: 광주광역시 서구 죽봉대로 70 | G39: 전북 전주시 완산구 쑥고개로 241-8 | I39: =IF(SUM(J39:U39)=0,"",SUM(J39:U39)) -> 1 | L39: 1 | W39: 0.00010385 | X39: 0.021461329 | Y39: 고속버스
B40: 대한민국 | C40: 광주전북지부 | D40: =IFERROR(INDEX(회사별_교통수단매핑!$C$2:$C$1000,MATCH(1,INDEX(($C$14=회사별_교통수단매핑!$A$2:$A$1000)*($Y40=회사별_교통수단매핑!$B$2:$B$1000),0),0)),"") -> 장거리버스/코치 | E40: 1 | F40: 광주광역시 서구 죽봉대로 71 | G40: 전북 전주시 완산구 용머리로 77 | I40: =IF(SUM(J40:U40)=0,"",SUM(J40:U40)) -> 1 | L40: 1 | W40: 0.00010385 | X40: 0.021461329 | Y40: 고속버스
B41: 대한민국 | C41: 광주전북지부 | D41: =IFERROR(INDEX(회사별_교통수단매핑!$C$2:$C$1000,MATCH(1,INDEX(($C$14=회사별_교통수단매핑!$A$2:$A$1000)*($Y41=회사별_교통수단매핑!$B$2:$B$1000),0),0)),"") -> 장거리버스/코치 | E41: 1 | F41: 광주광역시 서구 죽봉대로 72 | G41: 전북 전주시 완산구 전주객사3길 34 | I41: =IF(SUM(J41:U41)=0,"",SUM(J41:U41)) -> 1 | L41: 1 | W41: 0.00010385 | X41: 0.021461329 | Y41: 고속버스
B42: 대한민국 | C42: 광주전북지부 | D42: =IFERROR(INDEX(회사별_교통수단매핑!$C$2:$C$1000,MATCH(1,INDEX(($C$14=회사별_교통수단매핑!$A$2:$A$1000)*($Y42=회사별_교통수단매핑!$B$2:$B$1000),0),0)),"") -> 장거리버스/코치 | E42: 1 | F42: 광주광역시 서구 죽봉대로 73 | G42: 전북 전주시 완산구 팔달로 212-3 | I42: =IF(SUM(J42:U42)=0,"",SUM(J42:U42)) -> 2 | N42: 1 | P42: 1 | W42: 0.00010385 | X42: 0.042922657 | Y42: 고속버스
B43: 대한민국 | C43: 광주전북지부 | D43: =IFERROR(INDEX(회사별_교통수단매핑!$C$2:$C$1000,MATCH(1,INDEX(($C$14=회사별_교통수단매핑!$A$2:$A$1000)*($Y43=회사별_교통수단매핑!$B$2:$B$1000),0),0)),"") -> 장거리버스/코치 | E43: 1 | F43: 광주광역시 서구 죽봉대로 74 | G43: 전북 전주시 완산구 홍산로 111 | I43: =IF(SUM(J43:U43)=0,"",SUM(J43:U43)) -> 1 | N43: 1 | W43: 0.00010385 | X43: 0.021461329 | Y43: 고속버스
B44: 대한민국 | C44: 광주전북지부 | D44: =IFERROR(INDEX(회사별_교통수단매핑!$C$2:$C$1000,MATCH(1,INDEX(($C$14=회사별_교통수단매핑!$A$2:$A$1000)*($Y44=회사별_교통수단매핑!$B$2:$B$1000),0),0)),"") -> 장거리버스/코치 | E44: 1 | F44: 광주광역시 서구 죽봉대로 75 | G44: 전북 전주시 완산구 효자동1가 | I44: =IF(SUM(J44:U44)=0,"",SUM(J44:U44)) -> 1 | T44: 1 | W44: 0.00010385 | X44: 0.021461329 | Y44: 고속버스
...

Sheet 배출계수_드롭다운
A1: DD_PURCHASE_GROUP | B1: DD_ENERGY | C1: DD_ENERGY_UNIT | D1: DD_TRANSPORT_DISTANCE | E1: DD_TRANSPORT_SPEND | F1: DD_TRAVEL_DISTANCE | G1: DD_TRAVEL_SPEND | H1: DD_WASTE_C5_TYPE | I1: DD_WASTE_METHOD | J1: DD_WASTE_UNIT | K1: DD_TRANSPORT_WEIGHT_UNIT | M1: C6/C7 거리기반 상세 매핑
A2: C1/C2 구매·자본재 품목군 | B2: C3/C8/C11/C13/C14 에너지명 | C2: 에너지 기준단위 | D2: C4/C9 거리기반 운송수단 | E2: C4/C9 금액기반 운송항목 | F2: C6/C7 거리기반 교통수단 | G2: C6 금액기반 출장항목 | H2: C5 폐기물 종류 | I2: 폐기물 처리방법 | J2: 폐기물 중량단위 | K2: 운송 중량단위 | M2: 표시값(드롭다운) | N2: 표준코드 | O2: DEFRA Type | P2: 매핑 키워드
A3: 원재료/부자재 | B3: 도시가스(LNG) | C3: kWh | D3: 도로 운송 (일반화물트럭) | E3: 항공 운송(여객·화물·전세) | F3: 항공(국제선 평균) | G3: 항공권(여객·전세) | H3: 음식물류 폐기물 | I3: 매립 | J3: kg | K3: kg | M3: 항공(국제선 평균) | N3: flight | O3: International, non-UK - Average passenger | P3: 항공,비행기,비행,airplane,flight,국제선,해외출장
A4: 포장재 | B4: 천연가스(LNG) | C4: GJ | D4: 도로 운송 (택배·소화물) | E4: 철도 운송 | F4: 국내선 항공 | G4: 택시·리무진 비용 | H4: 폐지류 | I4: 소각 | J4: ton | K4: ton | M4: 국내선 항공 | N4: flight_dom | O4: Domestic, to/from UK - Average | P4: 국내선,국내항공,국내비행,domestic
A5: 사무용품 | B5: CNG(차량) | C5: L | D5: 철도 운송 | E5: 해상 운송(원양) | F5: 페리 | G5: 시외버스·고속버스 요금 | H5: 폐플라스틱류 | I5: 재활용 | M5: 페리 | N5: ferry | O5: Average (all passenger) | P5: 페리,ferry,선박,배
A6: 탕비·식음료 | B6: LNG(차량) | C6: kg | D6: 해상 운송 (컨테이너선) | E6: 내륙 수로 화물 | F6: 버스 | G6: 기차·KTX 요금 | H6: 폐목재류 | I6: 기타 | M6: 버스 | N6: bus | O6: Average local bus | P6: 버스,bus,고속버스,시외버스,시내버스,광역버스,전세버스,셔틀
A7: IT장비 | B7: LPG(차량) | C7: Nm³ | D7: 해상 운송 (벌크선) | E7: 화물 트럭(지역·이사) | F7: 장거리버스/코치 | G7: 렌터카·렌트 트럭 | H7: 폐섬유류 | M7: 장거리버스/코치 | N7: coach | O7: Coach | P7: 코치,장거리버스,express bus
A8: 사무가구·비품 | B8: 도시가스(LPG) | D8: 항공 운송 | E8: 장거리 화물 트럭 (차량단위) | F8: 철도/KTX/SRT | G8: 숙박비(호텔·게스트하우스 등) | H8: 폐유리류 | M8: 철도/KTX/SRT | N8: train | O8: National rail | P8: 기차,KTX,SRT,ITX,새마을,무궁화,열차,철도
A9: 시설·유지보수 | B9: 액화석유가스(LPG) | D9: 내륙수로 운송 | E9: 장거리 화물 트럭 (혼재) | F9: 지하철/도시철도 | H9: 폐금속류 | M9: 지하철/도시철도 | N9: subway | O9: London Underground / Metro | P9: 지하철,subway,metro,전철,도시철도
A10: 외주·서비스 | B10: 경유 | E10: 특수화물 트럭 (장거리) | F10: 택시 | H10: 오니류 | M10: 택시 | N10: taxi | O10: Regular taxi | P10: 택시,taxi,cab,카카오t,카카오택시,우버,uber
A11: 에너지·유틸리티 | B11: 실내 등유 | E11: 복합 대중교통 | F11: 승용차(평균) | H11: 폐전기전자제품 | M11: 승용차(평균) | N11: car | O11: Average car | P11: 승용차,자가용,car,차량,렌터카,자동차
A12: 차량·운송장비 | B12: 항공유 | E12: 버스(대중교통·통근·전세) | F12: 하이브리드차 | H12: 폐배터리 | M12: 하이브리드차 | N12: car_hybrid | O12: PHEV - Method 2 | P12: 하이브리드,hybrid,HEV,PHEV,플러그인하이브리드
A13: 생산설비 | B13: 휘발유 | E13: 기타 도시교통 | F13: 전기차 | H13: 폐유류 | M13: 전기차 | N13: car_ev | O13: BEV | P13: 전기차,전기자동차,EV,BEV,테슬라,아이오닉,EV6
A14: 안전·위생 | B14: 전력 | E14: 도시간·농촌 버스 | F14: 오토바이 | H14: 폐콘크리트류 | M14: 오토바이 | N14: motorcycle | O14: Average | P14: 오토바이,motorcycle,바이크
A15: 건설자재 | B15: 열(스팀) | E15: 택시·리무진 | F15: 도보/자전거 | H15: 폐고무/피혁류 | M15: 도보/자전거 | N15: walk | O15: 도보·자전거 | P15: 도보,자전거,walk,bicycle,bike
A16: 통신·미디어 | B16: 선택안함 | E16: 원유 파이프라인 | H16: 지정폐기물
A17: 여행·숙박 | E17: 화물운송 주선 (포워딩) | H17: 기타
A18: 기타 | E18: 택배·퀵배송 | H18: [전체 평균]
A19: 선택안함 | E19: 지역 배달
A38: ※ 본 시트의 드롭다운 목록은 업로드된 「배출계수_통합_DB」의 각 시트 값을 기준으로 생성했습니다. 템플릿의 입력값과 DB 기준명이 다른 경우에는 「드롭다운_매핑검토」의 매핑표를 참고하세요.

Sheet 드롭다운_매핑검토
A1: 구분 | B1: 템플릿 시트/범위 | C1: 기존 드롭다운/예시값 | D1: DB 기준 변경값 | E1: 조치
A2: 구매/자본재 | B2: C1 D20:D219, C2 D20:D219 | C2: 기존 품목군/자산분류 일부 | D2: 구매_USEPA!품목군 기준 | E2: DB 품목군으로 통일
A3: 에너지 | B3: C3/C8/C11/C13/C14 에너지명 | C3: 전기, 스팀, LPG 등 | D3: 에너지!활동유형(에너지원) 기준 | E3: 전기→전력, 스팀→열(스팀), LPG→액화석유가스(LPG) 등 매핑
A4: 에너지 단위 | B4: 에너지 단위 컬럼 | C4: m3, Nm3 등 | D4: 에너지!투입량 기준단위 기준 | E4: Nm³ 등 DB 표기 통일
A5: 운송 거리기반 | B5: C4-1/C9-1 운송수단 | C5: 도로/해상/항공/철도 | D5: 운송!운송수단(EPD 원본명) 기준 | E5: 세부 EF 단위로 상세화 및 내륙수로 추가
A6: 운송 금액기반 | B6: C4-2/C9-2 운송수단 | C6: 도로/해상/항공/철도 | D6: 운송_Spend!한국어 품목명 기준 | E6: 화물트럭 운송, 정기 항공화물 등으로 상세화 → 이후 배출계수(EF)가 완전히 동일한 항목끼리 재통합 (27→17개, 배출계수_통합_DB.xlsx의 운송_Spend 시트도 동일 기준으로 병합)
A7: 출장/통근 거리기반 | B7: C6-1/C7 교통수단 | C7: 자동차, 철도(KTX/SRT) 등 | D7: 출장_통근!표준코드/키워드 기준 | E7: DB 표준코드와 연결되는 한국어 표시값으로 정리 → 실사용 데이터(공연공 실적 1,200여 행) 기준 33개 중 실제로 쓰인 건 9개뿐이라, 좌석등급·차량크기 등 세부 구분(비즈니스/이코노미, 소형/중형/대형 등)을 13개로 축소(파이프라인 TRAVEL_EF_MAP의 세부 EF 코드 자체는 그대로 보존, 드롭다운만 정리)
A8: 출장비 | B8: C6-2 출장항목 | C8: 항공/철도/택시/렌터카/숙박/기타 | D8: 출장_Spend!한국어 품목명 기준 | E8: 여객 항공권, 기차·KTX 요금 등으로 상세화 → EF가 동일한 항목 병합 + 식비/통신비(DB에 배출계수 없음) 제거로 14→6개 축소, 배출계수_통합_DB.xlsx의 출장_Spend 시트도 동일 기준으로 병합
A9: 사업장폐기물 | B9: C5 폐기물종류/처리방법 | C9: 템플릿 임의목록 | D9: 폐기물_C5 기준 | E9: DB에 없는 항목은 지정폐기물/기타 등으로 매핑
A10: 판매제품폐기 | B10: C12 대/중/소분류 | C10: 기존 전체 법정 분류 목록 | D10: 폐기물_C12에 계수 있는 항목만 | E10: 소분류까지 DB 보유 항목 중심으로 축소·재구성
A11: 회사별 자동매칭 | B11: C5 폐기물종류 / C6-1·C7 교통수단 | C11: (신규 기능) | D11: '회사별_폐기물매핑'/'회사별_교통수단매핑' 시트 | E11: 표지(기업정보)에서 회사 선택 → 상세명(E열/Y열) 입력 시 표준값이 자동 매칭되는 수식 추가. 회사 목록은 '기업정보' 시트 E열에서 관리하고, 두 매핑 시트는 그 값을 그대로 참조
A12: 항공 거리계산(C6-1/C7) | B12: get_distance_km(mode="air") | C12: 주소 기준 직선거리 × 1.05 | D12: Climatiq/ICAO/DEFRA 벤치마킹 결과 | E12: 출도착지가 공항이 아니라 주소·지명이면 AI가 그 지역의 가까운 주요 공항으로 치환한 뒤 공항-공항 간 거리로 계산하도록 수정, 우회보정 계수도 1.05 → 1.09로 상향
A13: 주요 기존값 → DB 기준값 매핑
A14: 매핑그룹 | B14: 기존값 | C14: DB 기준값
A15: purchase_group | B15: 원재료 | C15: 원재료/부자재
A16: purchase_group | B16: 부자재 | C16: 원재료/부자재
A17: purchase_group | B17: 종이/인쇄물 | C17: 사무용품
A18: purchase_group | B18: IT/전자장비 | C18: IT장비
A19: purchase_group | B19: 소모품 | C19: 사무용품
A20: purchase_group | B20: 화학물질 | C20: 원재료/부자재
A21: purchase_group | B21: 금속/철강 | C21: 원재료/부자재
A22: purchase_group | B22: 플라스틱/고무 | C22: 원재료/부자재
A23: purchase_group | B23: 섬유/의류 | C23: 원재료/부자재
A24: purchase_group | B24: 식음료 | C24: 탕비·식음료
A25: purchase_group | B25: 운송/물류서비스 | C25: 외주·서비스
... A134: unit | B134: MJ | C134: MJ

Sheet 회사별_교통수단매핑
A1: 회사명 | B1: 상세 교통수단명 | C1: 표준 교통수단 | E1: 회사 목록(드롭다운용) | G1: '예시기업'는 형식을 보여주는 예시입니다. 회사 목록은 이 시트가 아니라 '기업정보' 시트의 E열에서 관리합니다(이 시트 E열은 그 값을 그대로 표시). 새 회사를 추가하려면: ① 이 시트 A~C열에 그 회사의 '상세 교통수단명 → 표준 교통수단' 행을 추가하고 ② '기업정보' 시트 E열에 회사명을 한 줄 추가하세요. 표준 교통수단은 반드시 '배출계수_드롭다운' 시트 F열(DD_TRAVEL_DISTANCE) 목록 값과 똑같이 입력해야 합니다.
A2: 공연공 | B2: 고속버스 | C2: 장거리버스/코치 | E2: =IF(기업정보!E2="","",기업정보!E2) -> 공연공
A3: 공연공 | B3: 국내선 항공 | C3: 국내선 항공
A4: 공연공 | B4: 자동차 | C4: 승용차(평균)
A5: 공연공 | B5: 철도(KTX/SRT) | C5: 철도/KTX/SRT
A6: 공연공 | B6: 기타(선박) | C6: 페리 | E6: =IF(기업정보!E6="","",기업정보!E6)
E7: =IF(기업정보!E7="","",기업정보!E7)
E8: =IF(기업정보!E8="","",기업정보!E8)
E9: =IF(기업정보!E9="","",기업정보!E9)
E10: =IF(기업정보!E10="","",기업정보!E10)
E11: =IF(기업정보!E11="","",기업정보!E11)
E12: =IF(기업정보!E12="","",기업정보!E12)
E13: =IF(기업정보!E13="","",기업정보!E13)
E14: =IF(기업정보!E14="","",기업정보!E14)
E15: =IF(기업정보!E15="","",기업정보!E15)
E16: =IF(기업정보!E16="","",기업정보!E16)
E17: =IF(기업정보!E17="","",기업정보!E17)
E18: =IF(기업정보!E18="","",기업정보!E18)
... E50: =IF(기업정보!E50="","",기업정보!E50)
